Workbook

Sheet ⚙️ NHẬP VIDEO
A1: 🎬 NHẬP LINK VIDEO ➜ TỰ ĐỘNG THÊM TỪ MỚI
A2: 🔗 LINK VIDEO ▸ dán vào đây | B2: https://www.youtube.com/watch?v=ZSxbxpU_qkM&list=PLSLog43d4VU8hPPOu5rOBvcsmMc9l0ZjY | C2: Dán link YouTube rồi chạy HA_video.bat
A3: 🔢 Số từ mới tối đa | B3: 100 | C3: Lấy N từ có tần suất cao nhất (0 = lấy hết)
A4: ✂️ Số ký tự tối thiểu | B4: 1 | C4: 2 = bỏ từ đơn 1 chữ; 1 = lấy cả từ 1 chữ
A5: 🚫 Bỏ hư từ thông dụng | B5: Có | C5: Có / Không (的, 了, 是, 我…)
A6: 🌐 Ngôn ngữ phụ đề | B6: auto | C6: auto hoặc zh-Hans / zh-TW
A7: 📊 TRẠNG THÁI | B7: ❌ Không tìm được chữ Hán trong video này | C7: Script tự cập nhật sau mỗi lần chạy
A8: 🎞️ Nguồn phụ đề | B8: auto | C8: auto / mota / dan / ocr
A9: 📜 LỊCH SỬ VIDEO ĐÃ XỬ LÝ
A10: 📅 NGÀY | B10: 🎬 VIDEO | C10: 🔗 LINK | D10: 🆕 TỪ MỚI | E10: 🔁 ĐÃ CÓ
A11: 2026-08-02 21:16 | B11: HSK 1–2 | 为什么学了很久还是不会说中文？| Why You Still Can’t Speak Chinese? | C11: ▶ Mở video | D11: 80 | E11: 167
A12: 2026-08-02 21:49 | B12: LẠI MUỐN TĂNG LƯƠNG NỮA SAO? 又要涨工资？ 又要漲工資？ Hoạt hình Tiếng Trung #dahuaxiyou | C12: ▶ Mở video | D12: 16 | E12: 6

Sheet 📋 DÁN PHỤ ĐỀ
A1: 📋 DÁN CHỮ HÁN VÀO ĐÂY (dùng khi video không có phụ đề) | E1: =COUNT(E4:E10485)
A2: Mỗi dòng 1 câu. Chép từ mô tả video / gõ lại chữ trên màn hình. Có lẫn tiếng Việt hay pinyin cũng được — script tự lọc. | E2: =COUNTIF(E4:E4100,E34)
A3: ▼ Bắt đầu dán từ dòng 4 ▼ | C3: 🔊 PINYIN (tự động) | D3: 🇻🇳 TIẾNG VIỆT (tự động, tra từ điển) | E3: date | F3: month | G3: year
A4: 今天公司里他打头很热闹 | C4: {=IF($A4="","",_xlfn.LET(_xlpm.s,$A4,_xlpm.dC,'📚 Từ Vựng HSK'!$C$4:$C$1025,_xlpm.dP,'📚 Từ Vựng HSK'!$D$4:$D$1025,_xlpm.dV,'📚 Từ Vựng HSK'!$E$4:$E$1025,_xlpm.md,1,_xlpm.res,_xlfn.REDUCE("0|",_xlfn.SEQUENCE(LEN(_xlpm.s)),_xlfn.LAMBDA(_xlpm.acc,_xlpm.idx,_xlfn.LET(_xlpm.sk,VALUE(LEFT(_xlpm.acc,FIND("|",_xlpm.acc)-1)),_xlpm.str,MID(_xlpm.acc,FIND("|",_xlpm.acc)+1,9999),IF(_xlpm.sk>0,(_xlpm.sk-1)&"|"&_xlpm.str,_xlfn.LET(_xlpm.ka,MID(_xlpm.s,_xlpm.idx,4),_xlpm.kb,MID(_xlpm.s,_xlpm.idx,3),_xlpm.kc,MID(_xlpm.s,_xlpm.idx,2),_xlpm.kd,MID(_xlpm.s,_xlpm.idx,1),_xlpm.pa,IF(LEN(_xlpm.ka)=4,IFERROR(MATCH(_xlpm.ka,_xlpm.dC,0),0),0),_xlpm.pb,IF(LEN(_xlpm.kb)=3,IFERROR(MATCH(_xlpm.kb,_xlpm.dC,0),0),0),_xlpm.pc,IF(LEN(_xlpm.kc)=2,IFERROR(MATCH(_xlpm.kc,_xlpm.dC,0),0),0),_xlpm.pd,IFERROR(MATCH(_xlpm.kd,_xlpm.dC,0),0),_xlpm.pos,IF(_xlpm.pa>0,_xlpm.pa,IF(_xlpm.pb>0,_xlpm.pb,IF(_xlpm.pc>0,_xlpm.pc,_xlpm.pd))),_xlpm.len,IF(_xlpm.pa>0,4,IF(_xlpm.pb>0,3,IF(_xlpm.pc>0,2,1))),_xlpm.wrd,IF(_xlpm.pos=0,_xlpm.kd,IF(_xlpm.md=1,INDEX(_xlpm.dP,_xlpm.pos),INDEX(_xlpm.dV,_xlpm.pos))),_xlpm.sep,IF(_xlpm.str="","",IF(_xlpm.md=1," "," / ")),(_xlpm.len-1)&"|"&_xlpm.str&_xlpm.sep&_xlpm.wrd))))),MID(_xlpm.res,FIND("|",_xlpm.res)+1,9999)))} | D4: {=IF($A4="","",_xlfn.LET(_xlpm.s,$A4,_xlpm.dC,'📚 Từ Vựng HSK'!$C$4:$C$1025,_xlpm.dP,'📚 Từ Vựng HSK'!$D$4:$D$1025,_xlpm.dV,'📚 Từ Vựng HSK'!$E$4:$E$1025,_xlpm.md,2,_xlpm.res,_xlfn.REDUCE("0|",_xlfn.SEQUENCE(LEN(_xlpm.s)),_xlfn.LAMBDA(_xlpm.acc,_xlpm.idx,_xlfn.LET(_xlpm.sk,VALUE(LEFT(_xlpm.acc,FIND("|",_xlpm.acc)-1)),_xlpm.str,MID(_xlpm.acc,FIND("|",_xlpm.acc)+1,9999),IF(_xlpm.sk>0,(_xlpm.sk-1)&"|"&_xlpm.str,_xlfn.LET(_xlpm.ka,MID(_xlpm.s,_xlpm.idx,4),_xlpm.kb,MID(_xlpm.s,_xlpm.idx,3),_xlpm.kc,MID(_xlpm.s,_xlpm.idx,2),_xlpm.kd,MID(_xlpm.s,_xlpm.idx,1),_xlpm.pa,IF(LEN(_xlpm.ka)=4,IFERROR(MATCH(_xlpm.ka,_xlpm.dC,0),0),0),_xlpm.pb,IF(LEN(_xlpm.kb)=3,IFERROR(MATCH(_xlpm.kb,_xlpm.dC,0),0),0),_xlpm.pc,IF(LEN(_xlpm.kc)=2,IFERROR(MATCH(_xlpm.kc,_xlpm.dC,0),0),0),_xlpm.pd,IFERROR(MATCH(_xlpm.kd,_xlpm.dC,0),0),_xlpm.pos,IF(_xlpm.pa>0,_xlpm.pa,IF(_xlpm.pb>0,_xlpm.pb,IF(_xlpm.pc>0,_xlpm.pc,_xlpm.pd))),_xlpm.len,IF(_xlpm.pa>0,4,IF(_xlpm.pb>0,3,IF(_xlpm.pc>0,2,1))),_xlpm.wrd,IF(_xlpm.pos=0,_xlpm.kd,IF(_xlpm.md=1,INDEX(_xlpm.dP,_xlpm.pos),INDEX(_xlpm.dV,_xlpm.pos))),_xlpm.sep,IF(_xlpm.str="","",IF(_xlpm.md=1," "," / ")),(_xlpm.len-1)&"|"&_xlpm.str&_xlpm.sep&_xlpm.wrd))))),MID(_xlpm.res,FIND("|",_xlpm.res)+1,9999)))} | E4: 46244
A5: 你们 常去 哪 吃 午饭 | C5: {=IF($A5="","",_xlfn.LET(_xlpm.s,$A5,_xlpm.dC,'📚 Từ Vựng HSK'!$C$4:$C$1025,_xlpm.dP,'📚 Từ Vựng HSK'!$D$4:$D$1025,_xlpm.dV,'📚 Từ Vựng HSK'!$E$4:$E$1025,_xlpm.md,1,_xlpm.res,_xlfn.REDUCE("0|",_xlfn.SEQUENCE(LEN(_xlpm.s)),_xlfn.LAMBDA(_xlpm.acc,_xlpm.idx,_xlfn.LET(_xlpm.sk,VALUE(LEFT(_xlpm.acc,FIND("|",_xlpm.acc)-1)),_xlpm.str,MID(_xlpm.acc,FIND("|",_xlpm.acc)+1,9999),IF(_xlpm.sk>0,(_xlpm.sk-1)&"|"&_xlpm.str,_xlfn.LET(_xlpm.ka,MID(_xlpm.s,_xlpm.idx,4),_xlpm.kb,MID(_xlpm.s,_xlpm.idx,3),_xlpm.kc,MID(_xlpm.s,_xlpm.idx,2),_xlpm.kd,MID(_xlpm.s,_xlpm.idx,1),_xlpm.pa,IF(LEN(_xlpm.ka)=4,IFERROR(MATCH(_xlpm.ka,_xlpm.dC,0),0),0),_xlpm.pb,IF(LEN(_xlpm.kb)=3,IFERROR(MATCH(_xlpm.kb,_xlpm.dC,0),0),0),_xlpm.pc,IF(LEN(_xlpm.kc)=2,IFERROR(MATCH(_xlpm.kc,_xlpm.dC,0),0),0),_xlpm.pd,IFERROR(MATCH(_xlpm.kd,_xlpm.dC,0),0),_xlpm.pos,IF(_xlpm.pa>0,_xlpm.pa,IF(_xlpm.pb>0,_xlpm.pb,IF(_xlpm.pc>0,_xlpm.pc,_xlpm.pd))),_xlpm.len,IF(_xlpm.pa>0,4,IF(_xlpm.pb>0,3,IF(_xlpm.pc>0,2,1))),_xlpm.wrd,IF(_xlpm.pos=0,_xlpm.kd,IF(_xlpm.md=1,INDEX(_xlpm.dP,_xlpm.pos),INDEX(_xlpm.dV,_xlpm.pos))),_xlpm.sep,IF(_xlpm.str="","",IF(_xlpm.md=1," "," / ")),(_xlpm.len-1)&"|"&_xlpm.str&_xlpm.sep&_xlpm.wrd))))),MID(_xlpm.res,FIND("|",_xlpm.res)+1,9999)))} | D5: {=IF($A5="","",_xlfn.LET(_xlpm.s,$A5,_xlpm.dC,'📚 Từ Vựng HSK'!$C$4:$C$1025,_xlpm.dP,'📚 Từ Vựng HSK'!$D$4:$D$1025,_xlpm.dV,'📚 Từ Vựng HSK'!$E$4:$E$1025,_xlpm.md,2,_xlpm.res,_xlfn.REDUCE("0|",_xlfn.SEQUENCE(LEN(_xlpm.s)),_xlfn.LAMBDA(_xlpm.acc,_xlpm.idx,_xlfn.LET(_xlpm.sk,VALUE(LEFT(_xlpm.acc,FIND("|",_xlpm.acc)-1)),_xlpm.str,MID(_xlpm.acc,FIND("|",_xlpm.acc)+1,9999),IF(_xlpm.sk>0,(_xlpm.sk-1)&"|"&_xlpm.str,_xlfn.LET(_xlpm.ka,MID(_xlpm.s,_xlpm.idx,4),_xlpm.kb,MID(_xlpm.s,_xlpm.idx,3),_xlpm.kc,MID(_xlpm.s,_xlpm.idx,2),_xlpm.kd,MID(_xlpm.s,_xlpm.idx,1),_xlpm.pa,IF(LEN(_xlpm.ka)=4,IFERROR(MATCH(_xlpm.ka,_xlpm.dC,0),0),0),_xlpm.pb,IF(LEN(_xlpm.kb)=3,IFERROR(MATCH(_xlpm.kb,_xlpm.dC,0),0),0),_xlpm.pc,IF(LEN(_xlpm.kc)=2,IFERROR(MATCH(_xlpm.kc,_xlpm.dC,0),0),0),_xlpm.pd,IFERROR(MATCH(_xlpm.kd,_xlpm.dC,0),0),_xlpm.pos,IF(_xlpm.pa>0,_xlpm.pa,IF(_xlpm.pb>0,_xlpm.pb,IF(_xlpm.pc>0,_xlpm.pc,_xlpm.pd))),_xlpm.len,IF(_xlpm.pa>0,4,IF(_xlpm.pb>0,3,IF(_xlpm.pc>0,2,1))),_xlpm.wrd,IF(_xlpm.pos=0,_xlpm.kd,IF(_xlpm.md=1,INDEX(_xlpm.dP,_xlpm.pos),INDEX(_xlpm.dV,_xlpm.pos))),_xlpm.sep,IF(_xlpm.str="","",IF(_xlpm.md=1," "," / ")),(_xlpm.len-1)&"|"&_xlpm.str&_xlpm.sep&_xlpm.wrd))))),MID(_xlpm.res,FIND("|",_xlpm.res)+1,9999)))} | E5: 46244
A6: 上课的时候你们不能说花 | C6: {=IF($A6="","",_xlfn.LET(_xlpm.s,$A6,_xlpm.dC,'📚 Từ Vựng HSK'!$C$4:$C$1025,_xlpm.dP,'📚 Từ Vựng HSK'!$D$4:$D$1025,_xlpm.dV,'📚 Từ Vựng HSK'!$E$4:$E$1025,_xlpm.md,1,_xlpm.res,_xlfn.REDUCE("0|",_xlfn.SEQUENCE(LEN(_xlpm.s)),_xlfn.LAMBDA(_xlpm.acc,_xlpm.idx,_xlfn.LET(_xlpm.sk,VALUE(LEFT(_xlpm.acc,FIND("|",_xlpm.acc)-1)),_xlpm.str,MID(_xlpm.acc,FIND("|",_xlpm.acc)+1,9999),IF(_xlpm.sk>0,(_xlpm.sk-1)&"|"&_xlpm.str,_xlfn.LET(_xlpm.ka,MID(_xlpm.s,_xlpm.idx,4),_xlpm.kb,MID(_xlpm.s,_xlpm.idx,3),_xlpm.kc,MID(_xlpm.s,_xlpm.idx,2),_xlpm.kd,MID(_xlpm.s,_xlpm.idx,1),_xlpm.pa,IF(LEN(_xlpm.ka)=4,IFERROR(MATCH(_xlpm.ka,_xlpm.dC,0),0),0),_xlpm.pb,IF(LEN(_xlpm.kb)=3,IFERROR(MATCH(_xlpm.kb,_xlpm.dC,0),0),0),_xlpm.pc,IF(LEN(_xlpm.kc)=2,IFERROR(MATCH(_xlpm.kc,_xlpm.dC,0),0),0),_xlpm.pd,IFERROR(MATCH(_xlpm.kd,_xlpm.dC,0),0),_xlpm.pos,IF(_xlpm.pa>0,_xlpm.pa,IF(_xlpm.pb>0,_xlpm.pb,IF(_xlpm.pc>0,_xlpm.pc,_xlpm.pd))),_xlpm.len,IF(_xlpm.pa>0,4,IF(_xlpm.pb>0,3,IF(_xlpm.pc>0,2,1))),_xlpm.wrd,IF(_xlpm.pos=0,_xlpm.kd,IF(_xlpm.md=1,INDEX(_xlpm.dP,_xlpm.pos),INDEX(_xlpm.dV,_xlpm.pos))),_xlpm.sep,IF(_xlpm.str="","",IF(_xlpm.md=1," "," / ")),(_xlpm.len-1)&"|"&_xlpm.str&_xlpm.sep&_xlpm.wrd))))),MID(_xlpm.res,FIND("|",_xlpm.res)+1,9999)))} | D6: {=IF($A6="","",_xlfn.LET(_xlpm.s,$A6,_xlpm.dC,'📚 Từ Vựng HSK'!$C$4:$C$1025,_xlpm.dP,'📚 Từ Vựng HSK'!$D$4:$D$1025,_xlpm.dV,'📚 Từ Vựng HSK'!$E$4:$E$1025,_xlpm.md,2,_xlpm.res,_xlfn.REDUCE("0|",_xlfn.SEQUENCE(LEN(_xlpm.s)),_xlfn.LAMBDA(_xlpm.acc,_xlpm.idx,_xlfn.LET(_xlpm.sk,VALUE(LEFT(_xlpm.acc,FIND("|",_xlpm.acc)-1)),_xlpm.str,MID(_xlpm.acc,FIND("|",_xlpm.acc)+1,9999),IF(_xlpm.sk>0,(_xlpm.sk-1)&"|"&_xlpm.str,_xlfn.LET(_xlpm.ka,MID(_xlpm.s,_xlpm.idx,4),_xlpm.kb,MID(_xlpm.s,_xlpm.idx,3),_xlpm.kc,MID(_xlpm.s,_xlpm.idx,2),_xlpm.kd,MID(_xlpm.s,_xlpm.idx,1),_xlpm.pa,IF(LEN(_xlpm.ka)=4,IFERROR(MATCH(_xlpm.ka,_xlpm.dC,0),0),0),_xlpm.pb,IF(LEN(_xlpm.kb)=3,IFERROR(MATCH(_xlpm.kb,_xlpm.dC,0),0),0),_xlpm.pc,IF(LEN(_xlpm.kc)=2,IFERROR(MATCH(_xlpm.kc,_xlpm.dC,0),0),0),_xlpm.pd,IFERROR(MATCH(_xlpm.kd,_xlpm.dC,0),0),_xlpm.pos,IF(_xlpm.pa>0,_xlpm.pa,IF(_xlpm.pb>0,_xlpm.pb,IF(_xlpm.pc>0,_xlpm.pc,_xlpm.pd))),_xlpm.len,IF(_xlpm.pa>0,4,IF(_xlpm.pb>0,3,IF(_xlpm.pc>0,2,1))),_xlpm.wrd,IF(_xlpm.pos=0,_xlpm.kd,IF(_xlpm.md=1,INDEX(_xlpm.dP,_xlpm.pos),INDEX(_xlpm.dV,_xlpm.pos))),_xlpm.sep,IF(_xlpm.str="","",IF(_xlpm.md=1," "," / ")),(_xlpm.len-1)&"|"&_xlpm.str&_xlpm.sep&_xlpm.wrd))))),MID(_xlpm.res,FIND("|",_xlpm.res)+1,9999)))} | E6: 46244
A7: 今天是第一天我做这个工作 | C7: {=IF($A7="","",_xlfn.LET(_xlpm.s,$A7,_xlpm.dC,'📚 Từ Vựng HSK'!$C$4:$C$1025,_xlpm.dP,'📚 Từ Vựng HSK'!$D$4:$D$1025,_xlpm.dV,'📚 Từ Vựng HSK'!$E$4:$E$1025,_xlpm.md,1,_xlpm.res,_xlfn.REDUCE("0|",_xlfn.SEQUENCE(LEN(_xlpm.s)),_xlfn.LAMBDA(_xlpm.acc,_xlpm.idx,_xlfn.LET(_xlpm.sk,VALUE(LEFT(_xlpm.acc,FIND("|",_xlpm.acc)-1)),_xlpm.str,MID(_xlpm.acc,FIND("|",_xlpm.acc)+1,9999),IF(_xlpm.sk>0,(_xlpm.sk-1)&"|"&_xlpm.str,_xlfn.LET(_xlpm.ka,MID(_xlpm.s,_xlpm.idx,4),_xlpm.kb,MID(_xlpm.s,_xlpm.idx,3),_xlpm.kc,MID(_xlpm.s,_xlpm.idx,2),_xlpm.kd,MID(_xlpm.s,_xlpm.idx,1),_xlpm.pa,IF(LEN(_xlpm.ka)=4,IFERROR(MATCH(_xlpm.ka,_xlpm.dC,0),0),0),_xlpm.pb,IF(LEN(_xlpm.kb)=3,IFERROR(MATCH(_xlpm.kb,_xlpm.dC,0),0),0),_xlpm.pc,IF(LEN(_xlpm.kc)=2,IFERROR(MATCH(_xlpm.kc,_xlpm.dC,0),0),0),_xlpm.pd,IFERROR(MATCH(_xlpm.kd,_xlpm.dC,0),0),_xlpm.pos,IF(_xlpm.pa>0,_xlpm.pa,IF(_xlpm.pb>0,_xlpm.pb,IF(_xlpm.pc>0,_xlpm.pc,_xlpm.pd))),_xlpm.len,IF(_xlpm.pa>0,4,IF(_xlpm.pb>0,3,IF(_xlpm.pc>0,2,1))),_xlpm.wrd,IF(_xlpm.pos=0,_xlpm.kd,IF(_xlpm.md=1,INDEX(_xlpm.dP,_xlpm.pos),INDEX(_xlpm.dV,_xlpm.pos))),_xlpm.sep,IF(_xlpm.str="","",IF(_xlpm.md=1," "," / ")),(_xlpm.len-1)&"|"&_xlpm.str&_xlpm.sep&_xlpm.wrd))))),MID(_xlpm.res,FIND("|",_xlpm.res)+1,9999)))} | D7: {=IF($A7="","",_xlfn.LET(_xlpm.s,$A7,_xlpm.dC,'📚 Từ Vựng HSK'!$C$4:$C$1025,_xlpm.dP,'📚 Từ Vựng HSK'!$D$4:$D$1025,_xlpm.dV,'📚 Từ Vựng HSK'!$E$4:$E$1025,_xlpm.md,2,_xlpm.res,_xlfn.REDUCE("0|",_xlfn.SEQUENCE(LEN(_xlpm.s)),_xlfn.LAMBDA(_xlpm.acc,_xlpm.idx,_xlfn.LET(_xlpm.sk,VALUE(LEFT(_xlpm.acc,FIND("|",_xlpm.acc)-1)),_xlpm.str,MID(_xlpm.acc,FIND("|",_xlpm.acc)+1,9999),IF(_xlpm.sk>0,(_xlpm.sk-1)&"|"&_xlpm.str,_xlfn.LET(_xlpm.ka,MID(_xlpm.s,_xlpm.idx,4),_xlpm.kb,MID(_xlpm.s,_xlpm.idx,3),_xlpm.kc,MID(_xlpm.s,_xlpm.idx,2),_xlpm.kd,MID(_xlpm.s,_xlpm.idx,1),_xlpm.pa,IF(LEN(_xlpm.ka)=4,IFERROR(MATCH(_xlpm.ka,_xlpm.dC,0),0),0),_xlpm.pb,IF(LEN(_xlpm.kb)=3,IFERROR(MATCH(_xlpm.kb,_xlpm.dC,0),0),0),_xlpm.pc,IF(LEN(_xlpm.kc)=2,IFERROR(MATCH(_xlpm.kc,_xlpm.dC,0),0),0),_xlpm.pd,IFERROR(MATCH(_xlpm.kd,_xlpm.dC,0),0),_xlpm.pos,IF(_xlpm.pa>0,_xlpm.pa,IF(_xlpm.pb>0,_xlpm.pb,IF(_xlpm.pc>0,_xlpm.pc,_xlpm.pd))),_xlpm.len,IF(_xlpm.pa>0,4,IF(_xlpm.pb>0,3,IF(_xlpm.pc>0,2,1))),_xlpm.wrd,IF(_xlpm.pos=0,_xlpm.kd,IF(_xlpm.md=1,INDEX(_xlpm.dP,_xlpm.pos),INDEX(_xlpm.dV,_xlpm.pos))),_xlpm.sep,IF(_xlpm.str="","",IF(_xlpm.md=1," "," / ")),(_xlpm.len-1)&"|"&_xlpm.str&_xlpm.sep&_xlpm.wrd))))),MID(_xlpm.res,FIND("|",_xlpm.res)+1,9999)))} | E7: 46244
A8: 这是第几次你们说话 | C8: {=IF($A8="","",_xlfn.LET(_xlpm.s,$A8,_xlpm.dC,'📚 Từ Vựng HSK'!$C$4:$C$1025,_xlpm.dP,'📚 Từ Vựng HSK'!$D$4:$D$1025,_xlpm.dV,'📚 Từ Vựng HSK'!$E$4:$E$1025,_xlpm.md,1,_xlpm.res,_xlfn.REDUCE("0|",_xlfn.SEQUENCE(LEN(_xlpm.s)),_xlfn.LAMBDA(_xlpm.acc,_xlpm.idx,_xlfn.LET(_xlpm.sk,VALUE(LEFT(_xlpm.acc,FIND("|",_xlpm.acc)-1)),_xlpm.str,MID(_xlpm.acc,FIND("|",_xlpm.acc)+1,9999),IF(_xlpm.sk>0,(_xlpm.sk-1)&"|"&_xlpm.str,_xlfn.LET(_xlpm.ka,MID(_xlpm.s,_xlpm.idx,4),_xlpm.kb,MID(_xlpm.s,_xlpm.idx,3),_xlpm.kc,MID(_xlpm.s,_xlpm.idx,2),_xlpm.kd,MID(_xlpm.s,_xlpm.idx,1),_xlpm.pa,IF(LEN(_xlpm.ka)=4,IFERROR(MATCH(_xlpm.ka,_xlpm.dC,0),0),0),_xlpm.pb,IF(LEN(_xlpm.kb)=3,IFERROR(MATCH(_xlpm.kb,_xlpm.dC,0),0),0),_xlpm.pc,IF(LEN(_xlpm.kc)=2,IFERROR(MATCH(_xlpm.kc,_xlpm.dC,0),0),0),_xlpm.pd,IFERROR(MATCH(_xlpm.kd,_xlpm.dC,0),0),_xlpm.pos,IF(_xlpm.pa>0,_xlpm.pa,IF(_xlpm.pb>0,_xlpm.pb,IF(_xlpm.pc>0,_xlpm.pc,_xlpm.pd))),_xlpm.len,IF(_xlpm.pa>0,4,IF(_xlpm.pb>0,3,IF(_xlpm.pc>0,2,1))),_xlpm.wrd,IF(_xlpm.pos=0,_xlpm.kd,IF(_xlpm.md=1,INDEX(_xlpm.dP,_xlpm.pos),INDEX(_xlpm.dV,_xlpm.pos))),_xlpm.sep,IF(_xlpm.str="","",IF(_xlpm.md=1," "," / ")),(_xlpm.len-1)&"|"&_xlpm.str&_xlpm.sep&_xlpm.wrd))))),MID(_xlpm.res,FIND("|",_xlpm.res)+1,9999)))} | D8: {=IF($A8="","",_xlfn.LET(_xlpm.s,$A8,_xlpm.dC,'📚 Từ Vựng HSK'!$C$4:$C$1025,_xlpm.dP,'📚 Từ Vựng HSK'!$D$4:$D$1025,_xlpm.dV,'📚 Từ Vựng HSK'!$E$4:$E$1025,_xlpm.md,2,_xlpm.res,_xlfn.REDUCE("0|",_xlfn.SEQUENCE(LEN(_xlpm.s)),_xlfn.LAMBDA(_xlpm.acc,_xlpm.idx,_xlfn.LET(_xlpm.sk,VALUE(LEFT(_xlpm.acc,FIND("|",_xlpm.acc)-1)),_xlpm.str,MID(_xlpm.acc,FIND("|",_xlpm.acc)+1,9999),IF(_xlpm.sk>0,(_xlpm.sk-1)&"|"&_xlpm.str,_xlfn.LET(_xlpm.ka,MID(_xlpm.s,_xlpm.idx,4),_xlpm.kb,MID(_xlpm.s,_xlpm.idx,3),_xlpm.kc,MID(_xlpm.s,_xlpm.idx,2),_xlpm.kd,MID(_xlpm.s,_xlpm.idx,1),_xlpm.pa,IF(LEN(_xlpm.ka)=4,IFERROR(MATCH(_xlpm.ka,_xlpm.dC,0),0),0),_xlpm.pb,IF(LEN(_xlpm.kb)=3,IFERROR(MATCH(_xlpm.kb,_xlpm.dC,0),0),0),_xlpm.pc,IF(LEN(_xlpm.kc)=2,IFERROR(MATCH(_xlpm.kc,_xlpm.dC,0),0),0),_xlpm.pd,IFERROR(MATCH(_xlpm.kd,_xlpm.dC,0),0),_xlpm.pos,IF(_xlpm.pa>0,_xlpm.pa,IF(_xlpm.pb>0,_xlpm.pb,IF(_xlpm.pc>0,_xlpm.pc,_xlpm.pd))),_xlpm.len,IF(_xlpm.pa>0,4,IF(_xlpm.pb>0,3,IF(_xlpm.pc>0,2,1))),_xlpm.wrd,IF(_xlpm.pos=0,_xlpm.kd,IF(_xlpm.md=1,INDEX(_xlpm.dP,_xlpm.pos),INDEX(_xlpm.dV,_xlpm.pos))),_xlpm.sep,IF(_xlpm.str="","",IF(_xlpm.md=1," "," / ")),(_xlpm.len-1)&"|"&_xlpm.str&_xlpm.sep&_xlpm.wrd))))),MID(_xlpm.res,FIND("|",_xlpm.res)+1,9999)))} | E8: 46244
A9: 你 觉得 汉语 难学吗？ | C9: {=IF($A9="","",_xlfn.LET(_xlpm.s,$A9,_xlpm.dC,'📚 Từ Vựng HSK'!$C$4:$C$1025,_xlpm.dP,'📚 Từ Vựng HSK'!$D$4:$D$1025,_xlpm.dV,'📚 Từ Vựng HSK'!$E$4:$E$1025,_xlpm.md,1,_xlpm.res,_xlfn.REDUCE("0|",_xlfn.SEQUENCE(LEN(_xlpm.s)),_xlfn.LAMBDA(_xlpm.acc,_xlpm.idx,_xlfn.LET(_xlpm.sk,VALUE(LEFT(_xlpm.acc,FIND("|",_xlpm.acc)-1)),_xlpm.str,MID(_xlpm.acc,FIND("|",_xlpm.acc)+1,9999),IF(_xlpm.sk>0,(_xlpm.sk-1)&"|"&_xlpm.str,_xlfn.LET(_xlpm.ka,MID(_xlpm.s,_xlpm.idx,4),_xlpm.kb,MID(_xlpm.s,_xlpm.idx,3),_xlpm.kc,MID(_xlpm.s,_xlpm.idx,2),_xlpm.kd,MID(_xlpm.s,_xlpm.idx,1),_xlpm.pa,IF(LEN(_xlpm.ka)=4,IFERROR(MATCH(_xlpm.ka,_xlpm.dC,0),0),0),_xlpm.pb,IF(LEN(_xlpm.kb)=3,IFERROR(MATCH(_xlpm.kb,_xlpm.dC,0),0),0),_xlpm.pc,IF(LEN(_xlpm.kc)=2,IFERROR(MATCH(_xlpm.kc,_xlpm.dC,0),0),0),_xlpm.pd,IFERROR(MATCH(_xlpm.kd,_xlpm.dC,0),0),_xlpm.pos,IF(_xlpm.pa>0,_xlpm.pa,IF(_xlpm.pb>0,_xlpm.pb,IF(_xlpm.pc>0,_xlpm.pc,_xlpm.pd))),_xlpm.len,IF(_xlpm.pa>0,4,IF(_xlpm.pb>0,3,IF(_xlpm.pc>0,2,1))),_xlpm.wrd,IF(_xlpm.pos=0,_xlpm.kd,IF(_xlpm.md=1,INDEX(_xlpm.dP,_xlpm.pos),INDEX(_xlpm.dV,_xlpm.pos))),_xlpm.sep,IF(_xlpm.str="","",IF(_xlpm.md=1," "," / ")),(_xlpm.len-1)&"|"&_xlpm.str&_xlpm.sep&_xlpm.wrd))))),MID(_xlpm.res,FIND("|",_xlpm.res)+1,9999)))} | D9: {=IF($A9="","",_xlfn.LET(_xlpm.s,$A9,_xlpm.dC,'📚 Từ Vựng HSK'!$C$4:$C$1025,_xlpm.dP,'📚 Từ Vựng HSK'!$D$4:$D$1025,_xlpm.dV,'📚 Từ Vựng HSK'!$E$4:$E$1025,_xlpm.md,2,_xlpm.res,_xlfn.REDUCE("0|",_xlfn.SEQUENCE(LEN(_xlpm.s)),_xlfn.LAMBDA(_xlpm.acc,_xlpm.idx,_xlfn.LET(_xlpm.sk,VALUE(LEFT(_xlpm.acc,FIND("|",_xlpm.acc)-1)),_xlpm.str,MID(_xlpm.acc,FIND("|",_xlpm.acc)+1,9999),IF(_xlpm.sk>0,(_xlpm.sk-1)&"|"&_xlpm.str,_xlfn.LET(_xlpm.ka,MID(_xlpm.s,_xlpm.idx,4),_xlpm.kb,MID(_xlpm.s,_xlpm.idx,3),_xlpm.kc,MID(_xlpm.s,_xlpm.idx,2),_xlpm.kd,MID(_xlpm.s,_xlpm.idx,1),_xlpm.pa,IF(LEN(_xlpm.ka)=4,IFERROR(MATCH(_xlpm.ka,_xlpm.dC,0),0),0),_xlpm.pb,IF(LEN(_xlpm.kb)=3,IFERROR(MATCH(_xlpm.kb,_xlpm.dC,0),0),0),_xlpm.pc,IF(LEN(_xlpm.kc)=2,IFERROR(MATCH(_xlpm.kc,_xlpm.dC,0),0),0),_xlpm.pd,IFERROR(MATCH(_xlpm.kd,_xlpm.dC,0),0),_xlpm.pos,IF(_xlpm.pa>0,_xlpm.pa,IF(_xlpm.pb>0,_xlpm.pb,IF(_xlpm.pc>0,_xlpm.pc,_xlpm.pd))),_xlpm.len,IF(_xlpm.pa>0,4,IF(_xlpm.pb>0,3,IF(_xlpm.pc>0,2,1))),_xlpm.wrd,IF(_xlpm.pos=0,_xlpm.kd,IF(_xlpm.md=1,INDEX(_xlpm.dP,_xlpm.pos),INDEX(_xlpm.dV,_xlpm.pos))),_xlpm.sep,IF(_xlpm.str="","",IF(_xlpm.md=1," "," / ")),(_xlpm.len-1)&"|"&_xlpm.str&_xlpm.sep&_xlpm.wrd))))),MID(_xlpm.res,FIND("|",_xlpm.res)+1,9999)))} | E9: 46244
A10: 这种 要 很男喝 | C10: {=IF($A10="","",_xlfn.LET(_xlpm.s,$A10,_xlpm.dC,'📚 Từ Vựng HSK'!$C$4:$C$1025,_xlpm.dP,'📚 Từ Vựng HSK'!$D$4:$D$1025,_xlpm.dV,'📚 Từ Vựng HSK'!$E$4:$E$1025,_xlpm.md,1,_xlpm.res,_xlfn.REDUCE("0|",_xlfn.SEQUENCE(LEN(_xlpm.s)),_xlfn.LAMBDA(_xlpm.acc,_xlpm.idx,_xlfn.LET(_xlpm.sk,VALUE(LEFT(_xlpm.acc,FIND("|",_xlpm.acc)-1)),_xlpm.str,MID(_xlpm.acc,FIND("|",_xlpm.acc)+1,9999),IF(_xlpm.sk>0,(_xlpm.sk-1)&"|"&_xlpm.str,_xlfn.LET(_xlpm.ka,MID(_xlpm.s,_xlpm.idx,4),_xlpm.kb,MID(_xlpm.s,_xlpm.idx,3),_xlpm.kc,MID(_xlpm.s,_xlpm.idx,2),_xlpm.kd,MID(_xlpm.s,_xlpm.idx,1),_xlpm.pa,IF(LEN(_xlpm.ka)=4,IFERROR(MATCH(_xlpm.ka,_xlpm.dC,0),0),0),_xlpm.pb,IF(LEN(_xlpm.kb)=3,IFERROR(MATCH(_xlpm.kb,_xlpm.dC,0),0),0),_xlpm.pc,IF(LEN(_xlpm.kc)=2,IFERROR(MATCH(_xlpm.kc,_xlpm.dC,0),0),0),_xlpm.pd,IFERROR(MATCH(_xlpm.kd,_xlpm.dC,0),0),_xlpm.pos,IF(_xlpm.pa>0,_xlpm.pa,IF(_xlpm.pb>0,_xlpm.pb,IF(_xlpm.pc>0,_xlpm.pc,_xlpm.pd))),_xlpm.len,IF(_xlpm.pa>0,4,IF(_xlpm.pb>0,3,IF(_xlpm.pc>0,2,1))),_xlpm.wrd,IF(_xlpm.pos=0,_xlpm.kd,IF(_xlpm.md=1,INDEX(_xlpm.dP,_xlpm.pos),INDEX(_xlpm.dV,_xlpm.pos))),_xlpm.sep,IF(_xlpm.str="","",IF(_xlpm.md=1," "," / ")),(_xlpm.len-1)&"|"&_xlpm.str&_xlpm.sep&_xlpm.wrd))))),MID(_xlpm.res,FIND("|",_xlpm.res)+1,9999)))} | D10: {=IF($A10="","",_xlfn.LET(_xlpm.s,$A10,_xlpm.dC,'📚 Từ Vựng HSK'!$C$4:$C$1025,_xlpm.dP,'📚 Từ Vựng HSK'!$D$4:$D$1025,_xlpm.dV,'📚 Từ Vựng HSK'!$E$4:$E$1025,_xlpm.md,2,_xlpm.res,_xlfn.REDUCE("0|",_xlfn.SEQUENCE(LEN(_xlpm.s)),_xlfn.LAMBDA(_xlpm.acc,_xlpm.idx,_xlfn.LET(_xlpm.sk,VALUE(LEFT(_xlpm.acc,FIND("|",_xlpm.acc)-1)),_xlpm.str,MID(_xlpm.acc,FIND("|",_xlpm.acc)+1,9999),IF(_xlpm.sk>0,(_xlpm.sk-1)&"|"&_xlpm.str,_xlfn.LET(_xlpm.ka,MID(_xlpm.s,_xlpm.idx,4),_xlpm.kb,MID(_xlpm.s,_xlpm.idx,3),_xlpm.kc,MID(_xlpm.s,_xlpm.idx,2),_xlpm.kd,MID(_xlpm.s,_xlpm.idx,1),_xlpm.pa,IF(LEN(_xlpm.ka)=4,IFERROR(MATCH(_xlpm.ka,_xlpm.dC,0),0),0),_xlpm.pb,IF(LEN(_xlpm.kb)=3,IFERROR(MATCH(_xlpm.kb,_xlpm.dC,0),0),0),_xlpm.pc,IF(LEN(_xlpm.kc)=2,IFERROR(MATCH(_xlpm.kc,_xlpm.dC,0),0),0),_xlpm.pd,IFERROR(MATCH(_xlpm.kd,_xlpm.dC,0),0),_xlpm.pos,IF(_xlpm.pa>0,_xlpm.pa,IF(_xlpm.pb>0,_xlpm.pb,IF(_xlpm.pc>0,_xlpm.pc,_xlpm.pd))),_xlpm.len,IF(_xlpm.pa>0,4,IF(_xlpm.pb>0,3,IF(_xlpm.pc>0,2,1))),_xlpm.wrd,IF(_xlpm.pos=0,_xlpm.kd,IF(_xlpm.md=1,INDEX(_xlpm.dP,_xlpm.pos),INDEX(_xlpm.dV,_xlpm.pos))),_xlpm.sep,IF(_xlpm.str="","",IF(_xlpm.md=1," "," / ")),(_xlpm.len-1)&"|"&_xlpm.str&_xlpm.sep&_xlpm.wrd))))),MID(_xlpm.res,FIND("|",_xlpm.res)+1,9999)))} | E10: 46244
A11: 最近他学习很进步 | C11: {=IF($A11="","",_xlfn.LET(_xlpm.s,$A11,_xlpm.dC,'📚 Từ Vựng HSK'!$C$4:$C$1025,_xlpm.dP,'📚 Từ Vựng HSK'!$D$4:$D$1025,_xlpm.dV,'📚 Từ Vựng HSK'!$E$4:$E$1025,_xlpm.md,1,_xlpm.res,_xlfn.REDUCE("0|",_xlfn.SEQUENCE(LEN(_xlpm.s)),_xlfn.LAMBDA(_xlpm.acc,_xlpm.idx,_xlfn.LET(_xlpm.sk,VALUE(LEFT(_xlpm.acc,FIND("|",_xlpm.acc)-1)),_xlpm.str,MID(_xlpm.acc,FIND("|",_xlpm.acc)+1,9999),IF(_xlpm.sk>0,(_xlpm.sk-1)&"|"&_xlpm.str,_xlfn.LET(_xlpm.ka,MID(_xlpm.s,_xlpm.idx,4),_xlpm.kb,MID(_xlpm.s,_xlpm.idx,3),_xlpm.kc,MID(_xlpm.s,_xlpm.idx,2),_xlpm.kd,MID(_xlpm.s,_xlpm.idx,1),_xlpm.pa,IF(LEN(_xlpm.ka)=4,IFERROR(MATCH(_xlpm.ka,_xlpm.dC,0),0),0),_xlpm.pb,IF(LEN(_xlpm.kb)=3,IFERROR(MATCH(_xlpm.kb,_xlpm.dC,0),0),0),_xlpm.pc,IF(LEN(_xlpm.kc)=2,IFERROR(MATCH(_xlpm.kc,_xlpm.dC,0),0),0),_xlpm.pd,IFERROR(MATCH(_xlpm.kd,_xlpm.dC,0),0),_xlpm.pos,IF(_xlpm.pa>0,_xlpm.pa,IF(_xlpm.pb>0,_xlpm.pb,IF(_xlpm.pc>0,_xlpm.pc,_xlpm.pd))),_xlpm.len,IF(_xlpm.pa>0,4,IF(_xlpm.pb>0,3,IF(_xlpm.pc>0,2,1))),_xlpm.wrd,IF(_xlpm.pos=0,_xlpm.kd,IF(_xlpm.md=1,INDEX(_xlpm.dP,_xlpm.pos),INDEX(_xlpm.dV,_xlpm.pos))),_xlpm.sep,IF(_xlpm.str="","",IF(_xlpm.md=1," "," / ")),(_xlpm.len-1)&"|"&_xlpm.str&_xlpm.sep&_xlpm.wrd))))),MID(_xlpm.res,FIND("|",_xlpm.res)+1,9999)))} | D11: {=IF($A11="","",_xlfn.LET(_xlpm.s,$A11,_xlpm.dC,'📚 Từ Vựng HSK'!$C$4:$C$1025,_xlpm.dP,'📚 Từ Vựng HSK'!$D$4:$D$1025,_xlpm.dV,'📚 Từ Vựng HSK'!$E$4:$E$1025,_xlpm.md,2,_xlpm.res,_xlfn.REDUCE("0|",_xlfn.SEQUENCE(LEN(_xlpm.s)),_xlfn.LAMBDA(_xlpm.acc,_xlpm.idx,_xlfn.LET(_xlpm.sk,VALUE(LEFT(_xlpm.acc,FIND("|",_xlpm.acc)-1)),_xlpm.str,MID(_xlpm.acc,FIND("|",_xlpm.acc)+1,9999),IF(_xlpm.sk>0,(_xlpm.sk-1)&"|"&_xlpm.str,_xlfn.LET(_xlpm.ka,MID(_xlpm.s,_xlpm.idx,4),_xlpm.kb,MID(_xlpm.s,_xlpm.idx,3),_xlpm.kc,MID(_xlpm.s,_xlpm.idx,2),_xlpm.kd,MID(_xlpm.s,_xlpm.idx,1),_xlpm.pa,IF(LEN(_xlpm.ka)=4,IFERROR(MATCH(_xlpm.ka,_xlpm.dC,0),0),0),_xlpm.pb,IF(LEN(_xlpm.kb)=3,IFERROR(MATCH(_xlpm.kb,_xlpm.dC,0),0),0),_xlpm.pc,IF(LEN(_xlpm.kc)=2,IFERROR(MATCH(_xlpm.kc,_xlpm.dC,0),0),0),_xlpm.pd,IFERROR(MATCH(_xlpm.kd,_xlpm.dC,0),0),_xlpm.pos,IF(_xlpm.pa>0,_xlpm.pa,IF(_xlpm.pb>0,_xlpm.pb,IF(_xlpm.pc>0,_xlpm.pc,_xlpm.pd))),_xlpm.len,IF(_xlpm.pa>0,4,IF(_xlpm.pb>0,3,IF(_xlpm.pc>0,2,1))),_xlpm.wrd,IF(_xlpm.pos=0,_xlpm.kd,IF(_xlpm.md=1,INDEX(_xlpm.dP,_xlpm.pos),INDEX(_xlpm.dV,_xlpm.pos))),_xlpm.sep,IF(_xlpm.str="","",IF(_xlpm.md=1," "," / ")),(_xlpm.len-1)&"|"&_xlpm.str&_xlpm.sep&_xlpm.wrd))))),MID(_xlpm.res,FIND("|",_xlpm.res)+1,9999)))} | E11: 46244
A12: 这个月她没有进步 | C12: {=IF($A12="","",_xlfn.LET(_xlpm.s,$A12,_xlpm.dC,'📚 Từ Vựng HSK'!$C$4:$C$1025,_xlpm.dP,'📚 Từ Vựng HSK'!$D$4:$D$1025,_xlpm.dV,'📚 Từ Vựng HSK'!$E$4:$E$1025,_xlpm.md,1,_xlpm.res,_xlfn.REDUCE("0|",_xlfn.SEQUENCE(LEN(_xlpm.s)),_xlfn.LAMBDA(_xlpm.acc,_xlpm.idx,_xlfn.LET(_xlpm.sk,VALUE(LEFT(_xlpm.acc,FIND("|",_xlpm.acc)-1)),_xlpm.str,MID(_xlpm.acc,FIND("|",_xlpm.acc)+1,9999),IF(_xlpm.sk>0,(_xlpm.sk-1)&"|"&_xlpm.str,_xlfn.LET(_xlpm.ka,MID(_xlpm.s,_xlpm.idx,4),_xlpm.kb,MID(_xlpm.s,_xlpm.idx,3),_xlpm.kc,MID(_xlpm.s,_xlpm.idx,2),_xlpm.kd,MID(_xlpm.s,_xlpm.idx,1),_xlpm.pa,IF(LEN(_xlpm.ka)=4,IFERROR(MATCH(_xlpm.ka,_xlpm.dC,0),0),0),_xlpm.pb,IF(LEN(_xlpm.kb)=3,IFERROR(MATCH(_xlpm.kb,_xlpm.dC,0),0),0),_xlpm.pc,IF(LEN(_xlpm.kc)=2,IFERROR(MATCH(_xlpm.kc,_xlpm.dC,0),0),0),_xlpm.pd,IFERROR(MATCH(_xlpm.kd,_xlpm.dC,0),0),_xlpm.pos,IF(_xlpm.pa>0,_xlpm.pa,IF(_xlpm.pb>0,_xlpm.pb,IF(_xlpm.pc>0,_xlpm.pc,_xlpm.pd))),_xlpm.len,IF(_xlpm.pa>0,4,IF(_xlpm.pb>0,3,IF(_xlpm.pc>0,2,1))),_xlpm.wrd,IF(_xlpm.pos=0,_xlpm.kd,IF(_xlpm.md=1,INDEX(_xlpm.dP,_xlpm.pos),INDEX(_xlpm.dV,_xlpm.pos))),_xlpm.sep,IF(_xlpm.str="","",IF(_xlpm.md=1," "," / ")),(_xlpm.len-1)&"|"&_xlpm.str&_xlpm.sep&_xlpm.wrd))))),MID(_xlpm.res,FIND("|",_xlpm.res)+1,9999)))} | D12: {=IF($A12="","",_xlfn.LET(_xlpm.s,$A12,_xlpm.dC,'📚 Từ Vựng HSK'!$C$4:$C$1025,_xlpm.dP,'📚 Từ Vựng HSK'!$D$4:$D$1025,_xlpm.dV,'📚 Từ Vựng HSK'!$E$4:$E$1025,_xlpm.md,2,_xlpm.res,_xlfn.REDUCE("0|",_xlfn.SEQUENCE(LEN(_xlpm.s)),_xlfn.LAMBDA(_xlpm.acc,_xlpm.idx,_xlfn.LET(_xlpm.sk,VALUE(LEFT(_xlpm.acc,FIND("|",_xlpm.acc)-1)),_xlpm.str,MID(_xlpm.acc,FIND("|",_xlpm.acc)+1,9999),IF(_xlpm.sk>0,(_xlpm.sk-1)&"|"&_xlpm.str,_xlfn.LET(_xlpm.ka,MID(_xlpm.s,_xlpm.idx,4),_xlpm.kb,MID(_xlpm.s,_xlpm.idx,3),_xlpm.kc,MID(_xlpm.s,_xlpm.idx,2),_xlpm.kd,MID(_xlpm.s,_xlpm.idx,1),_xlpm.pa,IF(LEN(_xlpm.ka)=4,IFERROR(MATCH(_xlpm.ka,_xlpm.dC,0),0),0),_xlpm.pb,IF(LEN(_xlpm.kb)=3,IFERROR(MATCH(_xlpm.kb,_xlpm.dC,0),0),0),_xlpm.pc,IF(LEN(_xlpm.kc)=2,IFERROR(MATCH(_xlpm.kc,_xlpm.dC,0),0),0),_xlpm.pd,IFERROR(MATCH(_xlpm.kd,_xlpm.dC,0),0),_xlpm.pos,IF(_xlpm.pa>0,_xlpm.pa,IF(_xlpm.pb>0,_xlpm.pb,IF(_xlpm.pc>0,_xlpm.pc,_xlpm.pd))),_xlpm.len,IF(_xlpm.pa>0,4,IF(_xlpm.pb>0,3,IF(_xlpm.pc>0,2,1))),_xlpm.wrd,IF(_xlpm.pos=0,_xlpm.kd,IF(_xlpm.md=1,INDEX(_xlpm.dP,_xlpm.pos),INDEX(_xlpm.dV,_xlpm.pos))),_xlpm.sep,IF(_xlpm.str="","",IF(_xlpm.md=1," "," / ")),(_xlpm.len-1)&"|"&_xlpm.str&_xlpm.sep&_xlpm.wrd))))),MID(_xlpm.res,FIND("|",_xlpm.res)+1,9999)))} | E12: 46244
A13: 你们 要努力学汉语 | C13: {=IF($A13="","",_xlfn.LET(_xlpm.s,$A13,_xlpm.dC,'📚 Từ Vựng HSK'!$C$4:$C$1025,_xlpm.dP,'📚 Từ Vựng HSK'!$D$4:$D$1025,_xlpm.dV,'📚 Từ Vựng HSK'!$E$4:$E$1025,_xlpm.md,1,_xlpm.res,_xlfn.REDUCE("0|",_xlfn.SEQUENCE(LEN(_xlpm.s)),_xlfn.LAMBDA(_xlpm.acc,_xlpm.idx,_xlfn.LET(_xlpm.sk,VALUE(LEFT(_xlpm.acc,FIND("|",_xlpm.acc)-1)),_xlpm.str,MID(_xlpm.acc,FIND("|",_xlpm.acc)+1,9999),IF(_xlpm.sk>0,(_xlpm.sk-1)&"|"&_xlpm.str,_xlfn.LET(_xlpm.ka,MID(_xlpm.s,_xlpm.idx,4),_xlpm.kb,MID(_xlpm.s,_xlpm.idx,3),_xlpm.kc,MID(_xlpm.s,_xlpm.idx,2),_xlpm.kd,MID(_xlpm.s,_xlpm.idx,1),_xlpm.pa,IF(LEN(_xlpm.ka)=4,IFERROR(MATCH(_xlpm.ka,_xlpm.dC,0),0),0),_xlpm.pb,IF(LEN(_xlpm.kb)=3,IFERROR(MATCH(_xlpm.kb,_xlpm.dC,0),0),0),_xlpm.pc,IF(LEN(_xlpm.kc)=2,IFERROR(MATCH(_xlpm.kc,_xlpm.dC,0),0),0),_xlpm.pd,IFERROR(MATCH(_xlpm.kd,_xlpm.dC,0),0),_xlpm.pos,IF(_xlpm.pa>0,_xlpm.pa,IF(_xlpm.pb>0,_xlpm.pb,IF(_xlpm.pc>0,_xlpm.pc,_xlpm.pd))),_xlpm.len,IF(_xlpm.pa>0,4,IF(_xlpm.pb>0,3,IF(_xlpm.pc>0,2,1))),_xlpm.wrd,IF(_xlpm.pos=0,_xlpm.kd,IF(_xlpm.md=1,INDEX(_xlpm.dP,_xlpm.pos),INDEX(_xlpm.dV,_xlpm.pos))),_xlpm.sep,IF(_xlpm.str="","",IF(_xlpm.md=1," "," / ")),(_xlpm.len-1)&"|"&_xlpm.str&_xlpm.sep&_xlpm.wrd))))),MID(_xlpm.res,FIND("|",_xlpm.res)+1,9999)))} | D13: {=IF($A13="","",_xlfn.LET(_xlpm.s,$A13,_xlpm.dC,'📚 Từ Vựng HSK'!$C$4:$C$1025,_xlpm.dP,'📚 Từ Vựng HSK'!$D$4:$D$1025,_xlpm.dV,'📚 Từ Vựng HSK'!$E$4:$E$1025,_xlpm.md,2,_xlpm.res,_xlfn.REDUCE("0|",_xlfn.SEQUENCE(LEN(_xlpm.s)),_xlfn.LAMBDA(_xlpm.acc,_xlpm.idx,_xlfn.LET(_xlpm.sk,VALUE(LEFT(_xlpm.acc,FIND("|",_xlpm.acc)-1)),_xlpm.str,MID(_xlpm.acc,FIND("|",_xlpm.acc)+1,9999),IF(_xlpm.sk>0,(_xlpm.sk-1)&"|"&_xlpm.str,_xlfn.LET(_xlpm.ka,MID(_xlpm.s,_xlpm.idx,4),_xlpm.kb,MID(_xlpm.s,_xlpm.idx,3),_xlpm.kc,MID(_xlpm.s,_xlpm.idx,2),_xlpm.kd,MID(_xlpm.s,_xlpm.idx,1),_xlpm.pa,IF(LEN(_xlpm.ka)=4,IFERROR(MATCH(_xlpm.ka,_xlpm.dC,0),0),0),_xlpm.pb,IF(LEN(_xlpm.kb)=3,IFERROR(MATCH(_xlpm.kb,_xlpm.dC,0),0),0),_xlpm.pc,IF(LEN(_xlpm.kc)=2,IFERROR(MATCH(_xlpm.kc,_xlpm.dC,0),0),0),_xlpm.pd,IFERROR(MATCH(_xlpm.kd,_xlpm.dC,0),0),_xlpm.pos,IF(_xlpm.pa>0,_xlpm.pa,IF(_xlpm.pb>0,_xlpm.pb,IF(_xlpm.pc>0,_xlpm.pc,_xlpm.pd))),_xlpm.len,IF(_xlpm.pa>0,4,IF(_xlpm.pb>0,3,IF(_xlpm.pc>0,2,1))),_xlpm.wrd,IF(_xlpm.pos=0,_xlpm.kd,IF(_xlpm.md=1,INDEX(_xlpm.dP,_xlpm.pos),INDEX(_xlpm.dV,_xlpm.pos))),_xlpm.sep,IF(_xlpm.str="","",IF(_xlpm.md=1," "," / ")),(_xlpm.len-1)&"|"&_xlpm.str&_xlpm.sep&_xlpm.wrd))))),MID(_xlpm.res,FIND("|",_xlpm.res)+1,9999)))} | E13: 46244
A14: 如果不努力工作 | C14: {=IF($A14="","",_xlfn.LET(_xlpm.s,$A14,_xlpm.dC,'📚 Từ Vựng HSK'!$C$4:$C$1025,_xlpm.dP,'📚 Từ Vựng HSK'!$D$4:$D$1025,_xlpm.dV,'📚 Từ Vựng HSK'!$E$4:$E$1025,_xlpm.md,1,_xlpm.res,_xlfn.REDUCE("0|",_xlfn.SEQUENCE(LEN(_xlpm.s)),_xlfn.LAMBDA(_xlpm.acc,_xlpm.idx,_xlfn.LET(_xlpm.sk,VALUE(LEFT(_xlpm.acc,FIND("|",_xlpm.acc)-1)),_xlpm.str,MID(_xlpm.acc,FIND("|",_xlpm.acc)+1,9999),IF(_xlpm.sk>0,(_xlpm.sk-1)&"|"&_xlpm.str,_xlfn.LET(_xlpm.ka,MID(_xlpm.s,_xlpm.idx,4),_xlpm.kb,MID(_xlpm.s,_xlpm.idx,3),_xlpm.kc,MID(_xlpm.s,_xlpm.idx,2),_xlpm.kd,MID(_xlpm.s,_xlpm.idx,1),_xlpm.pa,IF(LEN(_xlpm.ka)=4,IFERROR(MATCH(_xlpm.ka,_xlpm.dC,0),0),0),_xlpm.pb,IF(LEN(_xlpm.kb)=3,IFERROR(MATCH(_xlpm.kb,_xlpm.dC,0),0),0),_xlpm.pc,IF(LEN(_xlpm.kc)=2,IFERROR(MATCH(_xlpm.kc,_xlpm.dC,0),0),0),_xlpm.pd,IFERROR(MATCH(_xlpm.kd,_xlpm.dC,0),0),_xlpm.pos,IF(_xlpm.pa>0,_xlpm.pa,IF(_xlpm.pb>0,_xlpm.pb,IF(_xlpm.pc>0,_xlpm.pc,_xlpm.pd))),_xlpm.len,IF(_xlpm.pa>0,4,IF(_xlpm.pb>0,3,IF(_xlpm.pc>0,2,1))),_xlpm.wrd,IF(_xlpm.pos=0,_xlpm.kd,IF(_xlpm.md=1,INDEX(_xlpm.dP,_xlpm.pos),INDEX(_xlpm.dV,_xlpm.pos))),_xlpm.sep,IF(_xlpm.str="","",IF(_xlpm.md=1," "," / ")),(_xlpm.len-1)&"|"&_xlpm.str&_xlpm.sep&_xlpm.wrd))))),MID(_xlpm.res,FIND("|",_xlpm.res)+1,9999)))} | D14: {=IF($A14="","",_xlfn.LET(_xlpm.s,$A14,_xlpm.dC,'📚 Từ Vựng HSK'!$C$4:$C$1025,_xlpm.dP,'📚 Từ Vựng HSK'!$D$4:$D$1025,_xlpm.dV,'📚 Từ Vựng HSK'!$E$4:$E$1025,_xlpm.md,2,_xlpm.res,_xlfn.REDUCE("0|",_xlfn.SEQUENCE(LEN(_xlpm.s)),_xlfn.LAMBDA(_xlpm.acc,_xlpm.idx,_xlfn.LET(_xlpm.sk,VALUE(LEFT(_xlpm.acc,FIND("|",_xlpm.acc)-1)),_xlpm.str,MID(_xlpm.acc,FIND("|",_xlpm.acc)+1,9999),IF(_xlpm.sk>0,(_xlpm.sk-1)&"|"&_xlpm.str,_xlfn.LET(_xlpm.ka,MID(_xlpm.s,_xlpm.idx,4),_xlpm.kb,MID(_xlpm.s,_xlpm.idx,3),_xlpm.kc,MID(_xlpm.s,_xlpm.idx,2),_xlpm.kd,MID(_xlpm.s,_xlpm.idx,1),_xlpm.pa,IF(LEN(_xlpm.ka)=4,IFERROR(MATCH(_xlpm.ka,_xlpm.dC,0),0),0),_xlpm.pb,IF(LEN(_xlpm.kb)=3,IFERROR(MATCH(_xlpm.kb,_xlpm.dC,0),0),0),_xlpm.pc,IF(LEN(_xlpm.kc)=2,IFERROR(MATCH(_xlpm.kc,_xlpm.dC,0),0),0),_xlpm.pd,IFERROR(MATCH(_xlpm.kd,_xlpm.dC,0),0),_xlpm.pos,IF(_xlpm.pa>0,_xlpm.pa,IF(_xlpm.pb>0,_xlpm.pb,IF(_xlpm.pc>0,_xlpm.pc,_xlpm.pd))),_xlpm.len,IF(_xlpm.pa>0,4,IF(_xlpm.pb>0,3,IF(_xlpm.pc>0,2,1))),_xlpm.wrd,IF(_xlpm.pos=0,_xlpm.kd,IF(_xlpm.md=1,INDEX(_xlpm.dP,_xlpm.pos),INDEX(_xlpm.dV,_xlpm.pos))),_xlpm.sep,IF(_xlpm.str="","",IF(_xlpm.md=1," "," / ")),(_xlpm.len-1)&"|"&_xlpm.str&_xlpm.sep&_xlpm.wrd))))),MID(_xlpm.res,FIND("|",_xlpm.res)+1,9999)))} | E14: 46244
A15: 你们的老师的发音很准 | C15: {=IF($A15="","",_xlfn.LET(_xlpm.s,$A15,_xlpm.dC,'📚 Từ Vựng HSK'!$C$4:$C$1025,_xlpm.dP,'📚 Từ Vựng HSK'!$D$4:$D$1025,_xlpm.dV,'📚 Từ Vựng HSK'!$E$4:$E$1025,_xlpm.md,1,_xlpm.res,_xlfn.REDUCE("0|",_xlfn.SEQUENCE(LEN(_xlpm.s)),_xlfn.LAMBDA(_xlpm.acc,_xlpm.idx,_xlfn.LET(_xlpm.sk,VALUE(LEFT(_xlpm.acc,FIND("|",_xlpm.acc)-1)),_xlpm.str,MID(_xlpm.acc,FIND("|",_xlpm.acc)+1,9999),IF(_xlpm.sk>0,(_xlpm.sk-1)&"|"&_xlpm.str,_xlfn.LET(_xlpm.ka,MID(_xlpm.s,_xlpm.idx,4),_xlpm.kb,MID(_xlpm.s,_xlpm.idx,3),_xlpm.kc,MID(_xlpm.s,_xlpm.idx,2),_xlpm.kd,MID(_xlpm.s,_xlpm.idx,1),_xlpm.pa,IF(LEN(_xlpm.ka)=4,IFERROR(MATCH(_xlpm.ka,_xlpm.dC,0),0),0),_xlpm.pb,IF(LEN(_xlpm.kb)=3,IFERROR(MATCH(_xlpm.kb,_xlpm.dC,0),0),0),_xlpm.pc,IF(LEN(_xlpm.kc)=2,IFERROR(MATCH(_xlpm.kc,_xlpm.dC,0),0),0),_xlpm.pd,IFERROR(MATCH(_xlpm.kd,_xlpm.dC,0),0),_xlpm.pos,IF(_xlpm.pa>0,_xlpm.pa,IF(_xlpm.pb>0,_xlpm.pb,IF(_xlpm.pc>0,_xlpm.pc,_xlpm.pd))),_xlpm.len,IF(_xlpm.pa>0,4,IF(_xlpm.pb>0,3,IF(_xlpm.pc>0,2,1))),_xlpm.wrd,IF(_xlpm.pos=0,_xlpm.kd,IF(_xlpm.md=1,INDEX(_xlpm.dP,_xlpm.pos),INDEX(_xlpm.dV,_xlpm.pos))),_xlpm.sep,IF(_xlpm.str="","",IF(_xlpm.md=1," "," / ")),(_xlpm.len-1)&"|"&_xlpm.str&_xlpm.sep&_xlpm.wrd))))),MID(_xlpm.res,FIND("|",_xlpm.res)+1,9999)))} | D15: {=IF($A15="","",_xlfn.LET(_xlpm.s,$A15,_xlpm.dC,'📚 Từ Vựng HSK'!$C$4:$C$1025,_xlpm.dP,'📚 Từ Vựng HSK'!$D$4:$D$1025,_xlpm.dV,'📚 Từ Vựng HSK'!$E$4:$E$1025,_xlpm.md,2,_xlpm.res,_xlfn.REDUCE("0|",_xlfn.SEQUENCE(LEN(_xlpm.s)),_xlfn.LAMBDA(_xlpm.acc,_xlpm.idx,_xlfn.LET(_xlpm.sk,VALUE(LEFT(_xlpm.acc,FIND("|",_xlpm.acc)-1)),_xlpm.str,MID(_xlpm.acc,FIND("|",_xlpm.acc)+1,9999),IF(_xlpm.sk>0,(_xlpm.sk-1)&"|"&_xlpm.str,_xlfn.LET(_xlpm.ka,MID(_xlpm.s,_xlpm.idx,4),_xlpm.kb,MID(_xlpm.s,_xlpm.idx,3),_xlpm.kc,MID(_xlpm.s,_xlpm.idx,2),_xlpm.kd,MID(_xlpm.s,_xlpm.idx,1),_xlpm.pa,IF(LEN(_xlpm.ka)=4,IFERROR(MATCH(_xlpm.ka,_xlpm.dC,0),0),0),_xlpm.pb,IF(LEN(_xlpm.kb)=3,IFERROR(MATCH(_xlpm.kb,_xlpm.dC,0),0),0),_xlpm.pc,IF(LEN(_xlpm.kc)=2,IFERROR(MATCH(_xlpm.kc,_xlpm.dC,0),0),0),_xlpm.pd,IFERROR(MATCH(_xlpm.kd,_xlpm.dC,0),0),_xlpm.pos,IF(_xlpm.pa>0,_xlpm.pa,IF(_xlpm.pb>0,_xlpm.pb,IF(_xlpm.pc>0,_xlpm.pc,_xlpm.pd))),_xlpm.len,IF(_xlpm.pa>0,4,IF(_xlpm.pb>0,3,IF(_xlpm.pc>0,2,1))),_xlpm.wrd,IF(_xlpm.pos=0,_xlpm.kd,IF(_xlpm.md=1,INDEX(_xlpm.dP,_xlpm.pos),INDEX(_xlpm.dV,_xlpm.pos))),_xlpm.sep,IF(_xlpm.str="","",IF(_xlpm.md=1," "," / ")),(_xlpm.len-1)&"|"&_xlpm.str&_xlpm.sep&_xlpm.wrd))))),MID(_xlpm.res,FIND("|",_xlpm.res)+1,9999)))} | E15: 46244
... A63: 你可以上网叫电话费 | C63: {=IF($A63="","",_xlfn.LET(_xlpm.s,$A63,_xlpm.dC,'📚 Từ Vựng HSK'!$C$4:$C$1025,_xlpm.dP,'📚 Từ Vựng HSK'!$D$4:$D$1025,_xlpm.dV,'📚 Từ Vựng HSK'!$E$4:$E$1025,_xlpm.md,1,_xlpm.res,_xlfn.REDUCE("0|",_xlfn.SEQUENCE(LEN(_xlpm.s)),_xlfn.LAMBDA(_xlpm.acc,_xlpm.idx,_xlfn.LET(_xlpm.sk,VALUE(LEFT(_xlpm.acc,FIND("|",_xlpm.acc)-1)),_xlpm.str,MID(_xlpm.acc,FIND("|",_xlpm.acc)+1,9999),IF(_xlpm.sk>0,(_xlpm.sk-1)&"|"&_xlpm.str,_xlfn.LET(_xlpm.ka,MID(_xlpm.s,_xlpm.idx,4),_xlpm.kb,MID(_xlpm.s,_xlpm.idx,3),_xlpm.kc,MID(_xlpm.s,_xlpm.idx,2),_xlpm.kd,MID(_xlpm.s,_xlpm.idx,1),_xlpm.pa,IF(LEN(_xlpm.ka)=4,IFERROR(MATCH(_xlpm.ka,_xlpm.dC,0),0),0),_xlpm.pb,IF(LEN(_xlpm.kb)=3,IFERROR(MATCH(_xlpm.kb,_xlpm.dC,0),0),0),_xlpm.pc,IF(LEN(_xlpm.kc)=2,IFERROR(MATCH(_xlpm.kc,_xlpm.dC,0),0),0),_xlpm.pd,IFERROR(MATCH(_xlpm.kd,_xlpm.dC,0),0),_xlpm.pos,IF(_xlpm.pa>0,_xlpm.pa,IF(_xlpm.pb>0,_xlpm.pb,IF(_xlpm.pc>0,_xlpm.pc,_xlpm.pd))),_xlpm.len,IF(_xlpm.pa>0,4,IF(_xlpm.pb>0,3,IF(_xlpm.pc>0,2,1))),_xlpm.wrd,IF(_xlpm.pos=0,_xlpm.kd,IF(_xlpm.md=1,INDEX(_xlpm.dP,_xlpm.pos),INDEX(_xlpm.dV,_xlpm.pos))),_xlpm.sep,IF(_xlpm.str="","",IF(_xlpm.md=1," "," / ")),(_xlpm.len-1)&"|"&_xlpm.str&_xlpm.sep&_xlpm.wrd))))),MID(_xlpm.res,FIND("|",_xlpm.res)+1,9999)))} | D63: {=IF($A63="","",_xlfn.LET(_xlpm.s,$A63,_xlpm.dC,'📚 Từ Vựng HSK'!$C$4:$C$1025,_xlpm.dP,'📚 Từ Vựng HSK'!$D$4:$D$1025,_xlpm.dV,'📚 Từ Vựng HSK'!$E$4:$E$1025,_xlpm.md,2,_xlpm.res,_xlfn.REDUCE("0|",_xlfn.SEQUENCE(LEN(_xlpm.s)),_xlfn.LAMBDA(_xlpm.acc,_xlpm.idx,_xlfn.LET(_xlpm.sk,VALUE(LEFT(_xlpm.acc,FIND("|",_xlpm.acc)-1)),_xlpm.str,MID(_xlpm.acc,FIND("|",_xlpm.acc)+1,9999),IF(_xlpm.sk>0,(_xlpm.sk-1)&"|"&_xlpm.str,_xlfn.LET(_xlpm.ka,MID(_xlpm.s,_xlpm.idx,4),_xlpm.kb,MID(_xlpm.s,_xlpm.idx,3),_xlpm.kc,MID(_xlpm.s,_xlpm.idx,2),_xlpm.kd,MID(_xlpm.s,_xlpm.idx,1),_xlpm.pa,IF(LEN(_xlpm.ka)=4,IFERROR(MATCH(_xlpm.ka,_xlpm.dC,0),0),0),_xlpm.pb,IF(LEN(_xlpm.kb)=3,IFERROR(MATCH(_xlpm.kb,_xlpm.dC,0),0),0),_xlpm.pc,IF(LEN(_xlpm.kc)=2,IFERROR(MATCH(_xlpm.kc,_xlpm.dC,0),0),0),_xlpm.pd,IFERROR(MATCH(_xlpm.kd,_xlpm.dC,0),0),_xlpm.pos,IF(_xlpm.pa>0,_xlpm.pa,IF(_xlpm.pb>0,_xlpm.pb,IF(_xlpm.pc>0,_xlpm.pc,_xlpm.pd))),_xlpm.len,IF(_xlpm.pa>0,4,IF(_xlpm.pb>0,3,IF(_xlpm.pc>0,2,1))),_xlpm.wrd,IF(_xlpm.pos=0,_xlpm.kd,IF(_xlpm.md=1,INDEX(_xlpm.dP,_xlpm.pos),INDEX(_xlpm.dV,_xlpm.pos))),_xlpm.sep,IF(_xlpm.str="","",IF(_xlpm.md=1," "," / ")),(_xlpm.len-1)&"|"&_xlpm.str&_xlpm.sep&_xlpm.wrd))))),MID(_xlpm.res,FIND("|",_xlpm.res)+1,9999)))} | E63: 46245
C64: {=IF($A64="","",_xlfn.LET(_xlpm.s,$A64,_xlpm.dC,'📚 Từ Vựng HSK'!$C$4:$C$1025,_xlpm.dP,'📚 Từ Vựng HSK'!$D$4:$D$1025,_xlpm.dV,'📚 Từ Vựng HSK'!$E$4:$E$1025,_xlpm.md,1,_xlpm.res,_xlfn.REDUCE("0|",_xlfn.SEQUENCE(LEN(_xlpm.s)),_xlfn.LAMBDA(_xlpm.acc,_xlpm.idx,_xlfn.LET(_xlpm.sk,VALUE(LEFT(_xlpm.acc,FIND("|",_xlpm.acc)-1)),_xlpm.str,MID(_xlpm.acc,FIND("|",_xlpm.acc)+1,9999),IF(_xlpm.sk>0,(_xlpm.sk-1)&"|"&_xlpm.str,_xlfn.LET(_xlpm.ka,MID(_xlpm.s,_xlpm.idx,4),_xlpm.kb,MID(_xlpm.s,_xlpm.idx,3),_xlpm.kc,MID(_xlpm.s,_xlpm.idx,2),_xlpm.kd,MID(_xlpm.s,_xlpm.idx,1),_xlpm.pa,IF(LEN(_xlpm.ka)=4,IFERROR(MATCH(_xlpm.ka,_xlpm.dC,0),0),0),_xlpm.pb,IF(LEN(_xlpm.kb)=3,IFERROR(MATCH(_xlpm.kb,_xlpm.dC,0),0),0),_xlpm.pc,IF(LEN(_xlpm.kc)=2,IFERROR(MATCH(_xlpm.kc,_xlpm.dC,0),0),0),_xlpm.pd,IFERROR(MATCH(_xlpm.kd,_xlpm.dC,0),0),_xlpm.pos,IF(_xlpm.pa>0,_xlpm.pa,IF(_xlpm.pb>0,_xlpm.pb,IF(_xlpm.pc>0,_xlpm.pc,_xlpm.pd))),_xlpm.len,IF(_xlpm.pa>0,4,IF(_xlpm.pb>0,3,IF(_xlpm.pc>0,2,1))),_xlpm.wrd,IF(_xlpm.pos=0,_xlpm.kd,IF(_xlpm.md=1,INDEX(_xlpm.dP,_xlpm.pos),INDEX(_xlpm.dV,_xlpm.pos))),_xlpm.sep,IF(_xlpm.str="","",IF(_xlpm.md=1," "," / ")),(_xlpm.len-1)&"|"&_xlpm.str&_xlpm.sep&_xlpm.wrd))))),MID(_xlpm.res,FIND("|",_xlpm.res)+1,9999)))} | D64: {=IF($A64="","",_xlfn.LET(_xlpm.s,$A64,_xlpm.dC,'📚 Từ Vựng HSK'!$C$4:$C$1025,_xlpm.dP,'📚 Từ Vựng HSK'!$D$4:$D$1025,_xlpm.dV,'📚 Từ Vựng HSK'!$E$4:$E$1025,_xlpm.md,2,_xlpm.res,_xlfn.REDUCE("0|",_xlfn.SEQUENCE(LEN(_xlpm.s)),_xlfn.LAMBDA(_xlpm.acc,_xlpm.idx,_xlfn.LET(_xlpm.sk,VALUE(LEFT(_xlpm.acc,FIND("|",_xlpm.acc)-1)),_xlpm.str,MID(_xlpm.acc,FIND("|",_xlpm.acc)+1,9999),IF(_xlpm.sk>0,(_xlpm.sk-1)&"|"&_xlpm.str,_xlfn.LET(_xlpm.ka,MID(_xlpm.s,_xlpm.idx,4),_xlpm.kb,MID(_xlpm.s,_xlpm.idx,3),_xlpm.kc,MID(_xlpm.s,_xlpm.idx,2),_xlpm.kd,MID(_xlpm.s,_xlpm.idx,1),_xlpm.pa,IF(LEN(_xlpm.ka)=4,IFERROR(MATCH(_xlpm.ka,_xlpm.dC,0),0),0),_xlpm.pb,IF(LEN(_xlpm.kb)=3,IFERROR(MATCH(_xlpm.kb,_xlpm.dC,0),0),0),_xlpm.pc,IF(LEN(_xlpm.kc)=2,IFERROR(MATCH(_xlpm.kc,_xlpm.dC,0),0),0),_xlpm.pd,IFERROR(MATCH(_xlpm.kd,_xlpm.dC,0),0),_xlpm.pos,IF(_xlpm.pa>0,_xlpm.pa,IF(_xlpm.pb>0,_xlpm.pb,IF(_xlpm.pc>0,_xlpm.pc,_xlpm.pd))),_xlpm.len,IF(_xlpm.pa>0,4,IF(_xlpm.pb>0,3,IF(_xlpm.pc>0,2,1))),_xlpm.wrd,IF(_xlpm.pos=0,_xlpm.kd,IF(_xlpm.md=1,INDEX(_xlpm.dP,_xlpm.pos),INDEX(_xlpm.dV,_xlpm.pos))),_xlpm.sep,IF(_xlpm.str="","",IF(_xlpm.md=1," "," / ")),(_xlpm.len-1)&"|"&_xlpm.str&_xlpm.sep&_xlpm.wrd))))),MID(_xlpm.res,FIND("|",_xlpm.res)+1,9999)))}
C65: {=IF($A65="","",_xlfn.LET(_xlpm.s,$A65,_xlpm.dC,'📚 Từ Vựng HSK'!$C$4:$C$1025,_xlpm.dP,'📚 Từ Vựng HSK'!$D$4:$D$1025,_xlpm.dV,'📚 Từ Vựng HSK'!$E$4:$E$1025,_xlpm.md,1,_xlpm.res,_xlfn.REDUCE("0|",_xlfn.SEQUENCE(LEN(_xlpm.s)),_xlfn.LAMBDA(_xlpm.acc,_xlpm.idx,_xlfn.LET(_xlpm.sk,VALUE(LEFT(_xlpm.acc,FIND("|",_xlpm.acc)-1)),_xlpm.str,MID(_xlpm.acc,FIND("|",_xlpm.acc)+1,9999),IF(_xlpm.sk>0,(_xlpm.sk-1)&"|"&_xlpm.str,_xlfn.LET(_xlpm.ka,MID(_xlpm.s,_xlpm.idx,4),_xlpm.kb,MID(_xlpm.s,_xlpm.idx,3),_xlpm.kc,MID(_xlpm.s,_xlpm.idx,2),_xlpm.kd,MID(_xlpm.s,_xlpm.idx,1),_xlpm.pa,IF(LEN(_xlpm.ka)=4,IFERROR(MATCH(_xlpm.ka,_xlpm.dC,0),0),0),_xlpm.pb,IF(LEN(_xlpm.kb)=3,IFERROR(MATCH(_xlpm.kb,_xlpm.dC,0),0),0),_xlpm.pc,IF(LEN(_xlpm.kc)=2,IFERROR(MATCH(_xlpm.kc,_xlpm.dC,0),0),0),_xlpm.pd,IFERROR(MATCH(_xlpm.kd,_xlpm.dC,0),0),_xlpm.pos,IF(_xlpm.pa>0,_xlpm.pa,IF(_xlpm.pb>0,_xlpm.pb,IF(_xlpm.pc>0,_xlpm.pc,_xlpm.pd))),_xlpm.len,IF(_xlpm.pa>0,4,IF(_xlpm.pb>0,3,IF(_xlpm.pc>0,2,1))),_xlpm.wrd,IF(_xlpm.pos=0,_xlpm.kd,IF(_xlpm.md=1,INDEX(_xlpm.dP,_xlpm.pos),INDEX(_xlpm.dV,_xlpm.pos))),_xlpm.sep,IF(_xlpm.str="","",IF(_xlpm.md=1," "," / ")),(_xlpm.len-1)&"|"&_xlpm.str&_xlpm.sep&_xlpm.wrd))))),MID(_xlpm.res,FIND("|",_xlpm.res)+1,9999)))} | D65: {=IF($A65="","",_xlfn.LET(_xlpm.s,$A65,_xlpm.dC,'📚 Từ Vựng HSK'!$C$4:$C$1025,_xlpm.dP,'📚 Từ Vựng HSK'!$D$4:$D$1025,_xlpm.dV,'📚 Từ Vựng HSK'!$E$4:$E$1025,_xlpm.md,2,_xlpm.res,_xlfn.REDUCE("0|",_xlfn.SEQUENCE(LEN(_xlpm.s)),_xlfn.LAMBDA(_xlpm.acc,_xlpm.idx,_xlfn.LET(_xlpm.sk,VALUE(LEFT(_xlpm.acc,FIND("|",_xlpm.acc)-1)),_xlpm.str,MID(_xlpm.acc,FIND("|",_xlpm.acc)+1,9999),IF(_xlpm.sk>0,(_xlpm.sk-1)&"|"&_xlpm.str,_xlfn.LET(_xlpm.ka,MID(_xlpm.s,_xlpm.idx,4),_xlpm.kb,MID(_xlpm.s,_xlpm.idx,3),_xlpm.kc,MID(_xlpm.s,_xlpm.idx,2),_xlpm.kd,MID(_xlpm.s,_xlpm.idx,1),_xlpm.pa,IF(LEN(_xlpm.ka)=4,IFERROR(MATCH(_xlpm.ka,_xlpm.dC,0),0),0),_xlpm.pb,IF(LEN(_xlpm.kb)=3,IFERROR(MATCH(_xlpm.kb,_xlpm.dC,0),0),0),_xlpm.pc,IF(LEN(_xlpm.kc)=2,IFERROR(MATCH(_xlpm.kc,_xlpm.dC,0),0),0),_xlpm.pd,IFERROR(MATCH(_xlpm.kd,_xlpm.dC,0),0),_xlpm.pos,IF(_xlpm.pa>0,_xlpm.pa,IF(_xlpm.pb>0,_xlpm.pb,IF(_xlpm.pc>0,_xlpm.pc,_xlpm.pd))),_xlpm.len,IF(_xlpm.pa>0,4,IF(_xlpm.pb>0,3,IF(_xlpm.pc>0,2,1))),_xlpm.wrd,IF(_xlpm.pos=0,_xlpm.kd,IF(_xlpm.md=1,INDEX(_xlpm.dP,_xlpm.pos),INDEX(_xlpm.dV,_xlpm.pos))),_xlpm.sep,IF(_xlpm.str="","",IF(_xlpm.md=1," "," / ")),(_xlpm.len-1)&"|"&_xlpm.str&_xlpm.sep&_xlpm.wrd))))),MID(_xlpm.res,FIND("|",_xlpm.res)+1,9999)))}
C66: {=IF($A66="","",_xlfn.LET(_xlpm.s,$A66,_xlpm.dC,'📚 Từ Vựng HSK'!$C$4:$C$1025,_xlpm.dP,'📚 Từ Vựng HSK'!$D$4:$D$1025,_xlpm.dV,'📚 Từ Vựng HSK'!$E$4:$E$1025,_xlpm.md,1,_xlpm.res,_xlfn.REDUCE("0|",_xlfn.SEQUENCE(LEN(_xlpm.s)),_xlfn.LAMBDA(_xlpm.acc,_xlpm.idx,_xlfn.LET(_xlpm.sk,VALUE(LEFT(_xlpm.acc,FIND("|",_xlpm.acc)-1)),_xlpm.str,MID(_xlpm.acc,FIND("|",_xlpm.acc)+1,9999),IF(_xlpm.sk>0,(_xlpm.sk-1)&"|"&_xlpm.str,_xlfn.LET(_xlpm.ka,MID(_xlpm.s,_xlpm.idx,4),_xlpm.kb,MID(_xlpm.s,_xlpm.idx,3),_xlpm.kc,MID(_xlpm.s,_xlpm.idx,2),_xlpm.kd,MID(_xlpm.s,_xlpm.idx,1),_xlpm.pa,IF(LEN(_xlpm.ka)=4,IFERROR(MATCH(_xlpm.ka,_xlpm.dC,0),0),0),_xlpm.pb,IF(LEN(_xlpm.kb)=3,IFERROR(MATCH(_xlpm.kb,_xlpm.dC,0),0),0),_xlpm.pc,IF(LEN(_xlpm.kc)=2,IFERROR(MATCH(_xlpm.kc,_xlpm.dC,0),0),0),_xlpm.pd,IFERROR(MATCH(_xlpm.kd,_xlpm.dC,0),0),_xlpm.pos,IF(_xlpm.pa>0,_xlpm.pa,IF(_xlpm.pb>0,_xlpm.pb,IF(_xlpm.pc>0,_xlpm.pc,_xlpm.pd))),_xlpm.len,IF(_xlpm.pa>0,4,IF(_xlpm.pb>0,3,IF(_xlpm.pc>0,2,1))),_xlpm.wrd,IF(_xlpm.pos=0,_xlpm.kd,IF(_xlpm.md=1,INDEX(_xlpm.dP,_xlpm.pos),INDEX(_xlpm.dV,_xlpm.pos))),_xlpm.sep,IF(_xlpm.str="","",IF(_xlpm.md=1," "," / ")),(_xlpm.len-1)&"|"&_xlpm.str&_xlpm.sep&_xlpm.wrd))))),MID(_xlpm.res,FIND("|",_xlpm.res)+1,9999)))} | D66: {=IF($A66="","",_xlfn.LET(_xlpm.s,$A66,_xlpm.dC,'📚 Từ Vựng HSK'!$C$4:$C$1025,_xlpm.dP,'📚 Từ Vựng HSK'!$D$4:$D$1025,_xlpm.dV,'📚 Từ Vựng HSK'!$E$4:$E$1025,_xlpm.md,2,_xlpm.res,_xlfn.REDUCE("0|",_xlfn.SEQUENCE(LEN(_xlpm.s)),_xlfn.LAMBDA(_xlpm.acc,_xlpm.idx,_xlfn.LET(_xlpm.sk,VALUE(LEFT(_xlpm.acc,FIND("|",_xlpm.acc)-1)),_xlpm.str,MID(_xlpm.acc,FIND("|",_xlpm.acc)+1,9999),IF(_xlpm.sk>0,(_xlpm.sk-1)&"|"&_xlpm.str,_xlfn.LET(_xlpm.ka,MID(_xlpm.s,_xlpm.idx,4),_xlpm.kb,MID(_xlpm.s,_xlpm.idx,3),_xlpm.kc,MID(_xlpm.s,_xlpm.idx,2),_xlpm.kd,MID(_xlpm.s,_xlpm.idx,1),_xlpm.pa,IF(LEN(_xlpm.ka)=4,IFERROR(MATCH(_xlpm.ka,_xlpm.dC,0),0),0),_xlpm.pb,IF(LEN(_xlpm.kb)=3,IFERROR(MATCH(_xlpm.kb,_xlpm.dC,0),0),0),_xlpm.pc,IF(LEN(_xlpm.kc)=2,IFERROR(MATCH(_xlpm.kc,_xlpm.dC,0),0),0),_xlpm.pd,IFERROR(MATCH(_xlpm.kd,_xlpm.dC,0),0),_xlpm.pos,IF(_xlpm.pa>0,_xlpm.pa,IF(_xlpm.pb>0,_xlpm.pb,IF(_xlpm.pc>0,_xlpm.pc,_xlpm.pd))),_xlpm.len,IF(_xlpm.pa>0,4,IF(_xlpm.pb>0,3,IF(_xlpm.pc>0,2,1))),_xlpm.wrd,IF(_xlpm.pos=0,_xlpm.kd,IF(_xlpm.md=1,INDEX(_xlpm.dP,_xlpm.pos),INDEX(_xlpm.dV,_xlpm.pos))),_xlpm.sep,IF(_xlpm.str="","",IF(_xlpm.md=1," "," / ")),(_xlpm.len-1)&"|"&_xlpm.str&_xlpm.sep&_xlpm.wrd))))),MID(_xlpm.res,FIND("|",_xlpm.res)+1,9999)))}
C67: {=IF($A67="","",_xlfn.LET(_xlpm.s,$A67,_xlpm.dC,'📚 Từ Vựng HSK'!$C$4:$C$1025,_xlpm.dP,'📚 Từ Vựng HSK'!$D$4:$D$1025,_xlpm.dV,'📚 Từ Vựng HSK'!$E$4:$E$1025,_xlpm.md,1,_xlpm.res,_xlfn.REDUCE("0|",_xlfn.SEQUENCE(LEN(_xlpm.s)),_xlfn.LAMBDA(_xlpm.acc,_xlpm.idx,_xlfn.LET(_xlpm.sk,VALUE(LEFT(_xlpm.acc,FIND("|",_xlpm.acc)-1)),_xlpm.str,MID(_xlpm.acc,FIND("|",_xlpm.acc)+1,9999),IF(_xlpm.sk>0,(_xlpm.sk-1)&"|"&_xlpm.str,_xlfn.LET(_xlpm.ka,MID(_xlpm.s,_xlpm.idx,4),_xlpm.kb,MID(_xlpm.s,_xlpm.idx,3),_xlpm.kc,MID(_xlpm.s,_xlpm.idx,2),_xlpm.kd,MID(_xlpm.s,_xlpm.idx,1),_xlpm.pa,IF(LEN(_xlpm.ka)=4,IFERROR(MATCH(_xlpm.ka,_xlpm.dC,0),0),0),_xlpm.pb,IF(LEN(_xlpm.kb)=3,IFERROR(MATCH(_xlpm.kb,_xlpm.dC,0),0),0),_xlpm.pc,IF(LEN(_xlpm.kc)=2,IFERROR(MATCH(_xlpm.kc,_xlpm.dC,0),0),0),_xlpm.pd,IFERROR(MATCH(_xlpm.kd,_xlpm.dC,0),0),_xlpm.pos,IF(_xlpm.pa>0,_xlpm.pa,IF(_xlpm.pb>0,_xlpm.pb,IF(_xlpm.pc>0,_xlpm.pc,_xlpm.pd))),_xlpm.len,IF(_xlpm.pa>0,4,IF(_xlpm.pb>0,3,IF(_xlpm.pc>0,2,1))),_xlpm.wrd,IF(_xlpm.pos=0,_xlpm.kd,IF(_xlpm.md=1,INDEX(_xlpm.dP,_xlpm.pos),INDEX(_xlpm.dV,_xlpm.pos))),_xlpm.sep,IF(_xlpm.str="","",IF(_xlpm.md=1," "," / ")),(_xlpm.len-1)&"|"&_xlpm.str&_xlpm.sep&_xlpm.wrd))))),MID(_xlpm.res,FIND("|",_xlpm.res)+1,9999)))} | D67: {=IF($A67="","",_xlfn.LET(_xlpm.s,$A67,_xlpm.dC,'📚 Từ Vựng HSK'!$C$4:$C$1025,_xlpm.dP,'📚 Từ Vựng HSK'!$D$4:$D$1025,_xlpm.dV,'📚 Từ Vựng HSK'!$E$4:$E$1025,_xlpm.md,2,_xlpm.res,_xlfn.REDUCE("0|",_xlfn.SEQUENCE(LEN(_xlpm.s)),_xlfn.LAMBDA(_xlpm.acc,_xlpm.idx,_xlfn.LET(_xlpm.sk,VALUE(LEFT(_xlpm.acc,FIND("|",_xlpm.acc)-1)),_xlpm.str,MID(_xlpm.acc,FIND("|",_xlpm.acc)+1,9999),IF(_xlpm.sk>0,(_xlpm.sk-1)&"|"&_xlpm.str,_xlfn.LET(_xlpm.ka,MID(_xlpm.s,_xlpm.idx,4),_xlpm.kb,MID(_xlpm.s,_xlpm.idx,3),_xlpm.kc,MID(_xlpm.s,_xlpm.idx,2),_xlpm.kd,MID(_xlpm.s,_xlpm.idx,1),_xlpm.pa,IF(LEN(_xlpm.ka)=4,IFERROR(MATCH(_xlpm.ka,_xlpm.dC,0),0),0),_xlpm.pb,IF(LEN(_xlpm.kb)=3,IFERROR(MATCH(_xlpm.kb,_xlpm.dC,0),0),0),_xlpm.pc,IF(LEN(_xlpm.kc)=2,IFERROR(MATCH(_xlpm.kc,_xlpm.dC,0),0),0),_xlpm.pd,IFERROR(MATCH(_xlpm.kd,_xlpm.dC,0),0),_xlpm.pos,IF(_xlpm.pa>0,_xlpm.pa,IF(_xlpm.pb>0,_xlpm.pb,IF(_xlpm.pc>0,_xlpm.pc,_xlpm.pd))),_xlpm.len,IF(_xlpm.pa>0,4,IF(_xlpm.pb>0,3,IF(_xlpm.pc>0,2,1))),_xlpm.wrd,IF(_xlpm.pos=0,_xlpm.kd,IF(_xlpm.md=1,INDEX(_xlpm.dP,_xlpm.pos),INDEX(_xlpm.dV,_xlpm.pos))),_xlpm.sep,IF(_xlpm.str="","",IF(_xlpm.md=1," "," / ")),(_xlpm.len-1)&"|"&_xlpm.str&_xlpm.sep&_xlpm.wrd))))),MID(_xlpm.res,FIND("|",_xlpm.res)+1,9999)))}
C68: {=IF($A68="","",_xlfn.LET(_xlpm.s,$A68,_xlpm.dC,'📚 Từ Vựng HSK'!$C$4:$C$1025,_xlpm.dP,'📚 Từ Vựng HSK'!$D$4:$D$1025,_xlpm.dV,'📚 Từ Vựng HSK'!$E$4:$E$1025,_xlpm.md,1,_xlpm.res,_xlfn.REDUCE("0|",_xlfn.SEQUENCE(LEN(_xlpm.s)),_xlfn.LAMBDA(_xlpm.acc,_xlpm.idx,_xlfn.LET(_xlpm.sk,VALUE(LEFT(_xlpm.acc,FIND("|",_xlpm.acc)-1)),_xlpm.str,MID(_xlpm.acc,FIND("|",_xlpm.acc)+1,9999),IF(_xlpm.sk>0,(_xlpm.sk-1)&"|"&_xlpm.str,_xlfn.LET(_xlpm.ka,MID(_xlpm.s,_xlpm.idx,4),_xlpm.kb,MID(_xlpm.s,_xlpm.idx,3),_xlpm.kc,MID(_xlpm.s,_xlpm.idx,2),_xlpm.kd,MID(_xlpm.s,_xlpm.idx,1),_xlpm.pa,IF(LEN(_xlpm.ka)=4,IFERROR(MATCH(_xlpm.ka,_xlpm.dC,0),0),0),_xlpm.pb,IF(LEN(_xlpm.kb)=3,IFERROR(MATCH(_xlpm.kb,_xlpm.dC,0),0),0),_xlpm.pc,IF(LEN(_xlpm.kc)=2,IFERROR(MATCH(_xlpm.kc,_xlpm.dC,0),0),0),_xlpm.pd,IFERROR(MATCH(_xlpm.kd,_xlpm.dC,0),0),_xlpm.pos,IF(_xlpm.pa>0,_xlpm.pa,IF(_xlpm.pb>0,_xlpm.pb,IF(_xlpm.pc>0,_xlpm.pc,_xlpm.pd))),_xlpm.len,IF(_xlpm.pa>0,4,IF(_xlpm.pb>0,3,IF(_xlpm.pc>0,2,1))),_xlpm.wrd,IF(_xlpm.pos=0,_xlpm.kd,IF(_xlpm.md=1,INDEX(_xlpm.dP,_xlpm.pos),INDEX(_xlpm.dV,_xlpm.pos))),_xlpm.sep,IF(_xlpm.str="","",IF(_xlpm.md=1," "," / ")),(_xlpm.len-1)&"|"&_xlpm.str&_xlpm.sep&_xlpm.wrd))))),MID(_xlpm.res,FIND("|",_xlpm.res)+1,9999)))} | D68: {=IF($A68="","",_xlfn.LET(_xlpm.s,$A68,_xlpm.dC,'📚 Từ Vựng HSK'!$C$4:$C$1025,_xlpm.dP,'📚 Từ Vựng HSK'!$D$4:$D$1025,_xlpm.dV,'📚 Từ Vựng HSK'!$E$4:$E$1025,_xlpm.md,2,_xlpm.res,_xlfn.REDUCE("0|",_xlfn.SEQUENCE(LEN(_xlpm.s)),_xlfn.LAMBDA(_xlpm.acc,_xlpm.idx,_xlfn.LET(_xlpm.sk,VALUE(LEFT(_xlpm.acc,FIND("|",_xlpm.acc)-1)),_xlpm.str,MID(_xlpm.acc,FIND("|",_xlpm.acc)+1,9999),IF(_xlpm.sk>0,(_xlpm.sk-1)&"|"&_xlpm.str,_xlfn.LET(_xlpm.ka,MID(_xlpm.s,_xlpm.idx,4),_xlpm.kb,MID(_xlpm.s,_xlpm.idx,3),_xlpm.kc,MID(_xlpm.s,_xlpm.idx,2),_xlpm.kd,MID(_xlpm.s,_xlpm.idx,1),_xlpm.pa,IF(LEN(_xlpm.ka)=4,IFERROR(MATCH(_xlpm.ka,_xlpm.dC,0),0),0),_xlpm.pb,IF(LEN(_xlpm.kb)=3,IFERROR(MATCH(_xlpm.kb,_xlpm.dC,0),0),0),_xlpm.pc,IF(LEN(_xlpm.kc)=2,IFERROR(MATCH(_xlpm.kc,_xlpm.dC,0),0),0),_xlpm.pd,IFERROR(MATCH(_xlpm.kd,_xlpm.dC,0),0),_xlpm.pos,IF(_xlpm.pa>0,_xlpm.pa,IF(_xlpm.pb>0,_xlpm.pb,IF(_xlpm.pc>0,_xlpm.pc,_xlpm.pd))),_xlpm.len,IF(_xlpm.pa>0,4,IF(_xlpm.pb>0,3,IF(_xlpm.pc>0,2,1))),_xlpm.wrd,IF(_xlpm.pos=0,_xlpm.kd,IF(_xlpm.md=1,INDEX(_xlpm.dP,_xlpm.pos),INDEX(_xlpm.dV,_xlpm.pos))),_xlpm.sep,IF(_xlpm.str="","",IF(_xlpm.md=1," "," / ")),(_xlpm.len-1)&"|"&_xlpm.str&_xlpm.sep&_xlpm.wrd))))),MID(_xlpm.res,FIND("|",_xlpm.res)+1,9999)))}
C69: {=IF($A69="","",_xlfn.LET(_xlpm.s,$A69,_xlpm.dC,'📚 Từ Vựng HSK'!$C$4:$C$1025,_xlpm.dP,'📚 Từ Vựng HSK'!$D$4:$D$1025,_xlpm.dV,'📚 Từ Vựng HSK'!$E$4:$E$1025,_xlpm.md,1,_xlpm.res,_xlfn.REDUCE("0|",_xlfn.SEQUENCE(LEN(_xlpm.s)),_xlfn.LAMBDA(_xlpm.acc,_xlpm.idx,_xlfn.LET(_xlpm.sk,VALUE(LEFT(_xlpm.acc,FIND("|",_xlpm.acc)-1)),_xlpm.str,MID(_xlpm.acc,FIND("|",_xlpm.acc)+1,9999),IF(_xlpm.sk>0,(_xlpm.sk-1)&"|"&_xlpm.str,_xlfn.LET(_xlpm.ka,MID(_xlpm.s,_xlpm.idx,4),_xlpm.kb,MID(_xlpm.s,_xlpm.idx,3),_xlpm.kc,MID(_xlpm.s,_xlpm.idx,2),_xlpm.kd,MID(_xlpm.s,_xlpm.idx,1),_xlpm.pa,IF(LEN(_xlpm.ka)=4,IFERROR(MATCH(_xlpm.ka,_xlpm.dC,0),0),0),_xlpm.pb,IF(LEN(_xlpm.kb)=3,IFERROR(MATCH(_xlpm.kb,_xlpm.dC,0),0),0),_xlpm.pc,IF(LEN(_xlpm.kc)=2,IFERROR(MATCH(_xlpm.kc,_xlpm.dC,0),0),0),_xlpm.pd,IFERROR(MATCH(_xlpm.kd,_xlpm.dC,0),0),_xlpm.pos,IF(_xlpm.pa>0,_xlpm.pa,IF(_xlpm.pb>0,_xlpm.pb,IF(_xlpm.pc>0,_xlpm.pc,_xlpm.pd))),_xlpm.len,IF(_xlpm.pa>0,4,IF(_xlpm.pb>0,3,IF(_xlpm.pc>0,2,1))),_xlpm.wrd,IF(_xlpm.pos=0,_xlpm.kd,IF(_xlpm.md=1,INDEX(_xlpm.dP,_xlpm.pos),INDEX(_xlpm.dV,_xlpm.pos))),_xlpm.sep,IF(_xlpm.str="","",IF(_xlpm.md=1," "," / ")),(_xlpm.len-1)&"|"&_xlpm.str&_xlpm.sep&_xlpm.wrd))))),MID(_xlpm.res,FIND("|",_xlpm.res)+1,9999)))} | D69: {=IF($A69="","",_xlfn.LET(_xlpm.s,$A69,_xlpm.dC,'📚 Từ Vựng HSK'!$C$4:$C$1025,_xlpm.dP,'📚 Từ Vựng HSK'!$D$4:$D$1025,_xlpm.dV,'📚 Từ Vựng HSK'!$E$4:$E$1025,_xlpm.md,2,_xlpm.res,_xlfn.REDUCE("0|",_xlfn.SEQUENCE(LEN(_xlpm.s)),_xlfn.LAMBDA(_xlpm.acc,_xlpm.idx,_xlfn.LET(_xlpm.sk,VALUE(LEFT(_xlpm.acc,FIND("|",_xlpm.acc)-1)),_xlpm.str,MID(_xlpm.acc,FIND("|",_xlpm.acc)+1,9999),IF(_xlpm.sk>0,(_xlpm.sk-1)&"|"&_xlpm.str,_xlfn.LET(_xlpm.ka,MID(_xlpm.s,_xlpm.idx,4),_xlpm.kb,MID(_xlpm.s,_xlpm.idx,3),_xlpm.kc,MID(_xlpm.s,_xlpm.idx,2),_xlpm.kd,MID(_xlpm.s,_xlpm.idx,1),_xlpm.pa,IF(LEN(_xlpm.ka)=4,IFERROR(MATCH(_xlpm.ka,_xlpm.dC,0),0),0),_xlpm.pb,IF(LEN(_xlpm.kb)=3,IFERROR(MATCH(_xlpm.kb,_xlpm.dC,0),0),0),_xlpm.pc,IF(LEN(_xlpm.kc)=2,IFERROR(MATCH(_xlpm.kc,_xlpm.dC,0),0),0),_xlpm.pd,IFERROR(MATCH(_xlpm.kd,_xlpm.dC,0),0),_xlpm.pos,IF(_xlpm.pa>0,_xlpm.pa,IF(_xlpm.pb>0,_xlpm.pb,IF(_xlpm.pc>0,_xlpm.pc,_xlpm.pd))),_xlpm.len,IF(_xlpm.pa>0,4,IF(_xlpm.pb>0,3,IF(_xlpm.pc>0,2,1))),_xlpm.wrd,IF(_xlpm.pos=0,_xlpm.kd,IF(_xlpm.md=1,INDEX(_xlpm.dP,_xlpm.pos),INDEX(_xlpm.dV,_xlpm.pos))),_xlpm.sep,IF(_xlpm.str="","",IF(_xlpm.md=1," "," / ")),(_xlpm.len-1)&"|"&_xlpm.str&_xlpm.sep&_xlpm.wrd))))),MID(_xlpm.res,FIND("|",_xlpm.res)+1,9999)))}
C70: {=IF($A70="","",_xlfn.LET(_xlpm.s,$A70,_xlpm.dC,'📚 Từ Vựng HSK'!$C$4:$C$1025,_xlpm.dP,'📚 Từ Vựng HSK'!$D$4:$D$1025,_xlpm.dV,'📚 Từ Vựng HSK'!$E$4:$E$1025,_xlpm.md,1,_xlpm.res,_xlfn.REDUCE("0|",_xlfn.SEQUENCE(LEN(_xlpm.s)),_xlfn.LAMBDA(_xlpm.acc,_xlpm.idx,_xlfn.LET(_xlpm.sk,VALUE(LEFT(_xlpm.acc,FIND("|",_xlpm.acc)-1)),_xlpm.str,MID(_xlpm.acc,FIND("|",_xlpm.acc)+1,9999),IF(_xlpm.sk>0,(_xlpm.sk-1)&"|"&_xlpm.str,_xlfn.LET(_xlpm.ka,MID(_xlpm.s,_xlpm.idx,4),_xlpm.kb,MID(_xlpm.s,_xlpm.idx,3),_xlpm.kc,MID(_xlpm.s,_xlpm.idx,2),_xlpm.kd,MID(_xlpm.s,_xlpm.idx,1),_xlpm.pa,IF(LEN(_xlpm.ka)=4,IFERROR(MATCH(_xlpm.ka,_xlpm.dC,0),0),0),_xlpm.pb,IF(LEN(_xlpm.kb)=3,IFERROR(MATCH(_xlpm.kb,_xlpm.dC,0),0),0),_xlpm.pc,IF(LEN(_xlpm.kc)=2,IFERROR(MATCH(_xlpm.kc,_xlpm.dC,0),0),0),_xlpm.pd,IFERROR(MATCH(_xlpm.kd,_xlpm.dC,0),0),_xlpm.pos,IF(_xlpm.pa>0,_xlpm.pa,IF(_xlpm.pb>0,_xlpm.pb,IF(_xlpm.pc>0,_xlpm.pc,_xlpm.pd))),_xlpm.len,IF(_xlpm.pa>0,4,IF(_xlpm.pb>0,3,IF(_xlpm.pc>0,2,1))),_xlpm.wrd,IF(_xlpm.pos=0,_xlpm.kd,IF(_xlpm.md=1,INDEX(_xlpm.dP,_xlpm.pos),INDEX(_xlpm.dV,_xlpm.pos))),_xlpm.sep,IF(_xlpm.str="","",IF(_xlpm.md=1," "," / ")),(_xlpm.len-1)&"|"&_xlpm.str&_xlpm.sep&_xlpm.wrd))))),MID(_xlpm.res,FIND("|",_xlpm.res)+1,9999)))} | D70: {=IF($A70="","",_xlfn.LET(_xlpm.s,$A70,_xlpm.dC,'📚 Từ Vựng HSK'!$C$4:$C$1025,_xlpm.dP,'📚 Từ Vựng HSK'!$D$4:$D$1025,_xlpm.dV,'📚 Từ Vựng HSK'!$E$4:$E$1025,_xlpm.md,2,_xlpm.res,_xlfn.REDUCE("0|",_xlfn.SEQUENCE(LEN(_xlpm.s)),_xlfn.LAMBDA(_xlpm.acc,_xlpm.idx,_xlfn.LET(_xlpm.sk,VALUE(LEFT(_xlpm.acc,FIND("|",_xlpm.acc)-1)),_xlpm.str,MID(_xlpm.acc,FIND("|",_xlpm.acc)+1,9999),IF(_xlpm.sk>0,(_xlpm.sk-1)&"|"&_xlpm.str,_xlfn.LET(_xlpm.ka,MID(_xlpm.s,_xlpm.idx,4),_xlpm.kb,MID(_xlpm.s,_xlpm.idx,3),_xlpm.kc,MID(_xlpm.s,_xlpm.idx,2),_xlpm.kd,MID(_xlpm.s,_xlpm.idx,1),_xlpm.pa,IF(LEN(_xlpm.ka)=4,IFERROR(MATCH(_xlpm.ka,_xlpm.dC,0),0),0),_xlpm.pb,IF(LEN(_xlpm.kb)=3,IFERROR(MATCH(_xlpm.kb,_xlpm.dC,0),0),0),_xlpm.pc,IF(LEN(_xlpm.kc)=2,IFERROR(MATCH(_xlpm.kc,_xlpm.dC,0),0),0),_xlpm.pd,IFERROR(MATCH(_xlpm.kd,_xlpm.dC,0),0),_xlpm.pos,IF(_xlpm.pa>0,_xlpm.pa,IF(_xlpm.pb>0,_xlpm.pb,IF(_xlpm.pc>0,_xlpm.pc,_xlpm.pd))),_xlpm.len,IF(_xlpm.pa>0,4,IF(_xlpm.pb>0,3,IF(_xlpm.pc>0,2,1))),_xlpm.wrd,IF(_xlpm.pos=0,_xlpm.kd,IF(_xlpm.md=1,INDEX(_xlpm.dP,_xlpm.pos),INDEX(_xlpm.dV,_xlpm.pos))),_xlpm.sep,IF(_xlpm.str="","",IF(_xlpm.md=1," "," / ")),(_xlpm.len-1)&"|"&_xlpm.str&_xlpm.sep&_xlpm.wrd))))),MID(_xlpm.res,FIND("|",_xlpm.res)+1,9999)))}
C71: {=IF($A71="","",_xlfn.LET(_xlpm.s,$A71,_xlpm.dC,'📚 Từ Vựng HSK'!$C$4:$C$1025,_xlpm.dP,'📚 Từ Vựng HSK'!$D$4:$D$1025,_xlpm.dV,'📚 Từ Vựng HSK'!$E$4:$E$1025,_xlpm.md,1,_xlpm.res,_xlfn.REDUCE("0|",_xlfn.SEQUENCE(LEN(_xlpm.s)),_xlfn.LAMBDA(_xlpm.acc,_xlpm.idx,_xlfn.LET(_xlpm.sk,VALUE(LEFT(_xlpm.acc,FIND("|",_xlpm.acc)-1)),_xlpm.str,MID(_xlpm.acc,FIND("|",_xlpm.acc)+1,9999),IF(_xlpm.sk>0,(_xlpm.sk-1)&"|"&_xlpm.str,_xlfn.LET(_xlpm.ka,MID(_xlpm.s,_xlpm.idx,4),_xlpm.kb,MID(_xlpm.s,_xlpm.idx,3),_xlpm.kc,MID(_xlpm.s,_xlpm.idx,2),_xlpm.kd,MID(_xlpm.s,_xlpm.idx,1),_xlpm.pa,IF(LEN(_xlpm.ka)=4,IFERROR(MATCH(_xlpm.ka,_xlpm.dC,0),0),0),_xlpm.pb,IF(LEN(_xlpm.kb)=3,IFERROR(MATCH(_xlpm.kb,_xlpm.dC,0),0),0),_xlpm.pc,IF(LEN(_xlpm.kc)=2,IFERROR(MATCH(_xlpm.kc,_xlpm.dC,0),0),0),_xlpm.pd,IFERROR(MATCH(_xlpm.kd,_xlpm.dC,0),0),_xlpm.pos,IF(_xlpm.pa>0,_xlpm.pa,IF(_xlpm.pb>0,_xlpm.pb,IF(_xlpm.pc>0,_xlpm.pc,_xlpm.pd))),_xlpm.len,IF(_xlpm.pa>0,4,IF(_xlpm.pb>0,3,IF(_xlpm.pc>0,2,1))),_xlpm.wrd,IF(_xlpm.pos=0,_xlpm.kd,IF(_xlpm.md=1,INDEX(_xlpm.dP,_xlpm.pos),INDEX(_xlpm.dV,_xlpm.pos))),_xlpm.sep,IF(_xlpm.str="","",IF(_xlpm.md=1," "," / ")),(_xlpm.len-1)&"|"&_xlpm.str&_xlpm.sep&_xlpm.wrd))))),MID(_xlpm.res,FIND("|",_xlpm.res)+1,9999)))} | D71: {=IF($A71="","",_xlfn.LET(_xlpm.s,$A71,_xlpm.dC,'📚 Từ Vựng HSK'!$C$4:$C$1025,_xlpm.dP,'📚 Từ Vựng HSK'!$D$4:$D$1025,_xlpm.dV,'📚 Từ Vựng HSK'!$E$4:$E$1025,_xlpm.md,2,_xlpm.res,_xlfn.REDUCE("0|",_xlfn.SEQUENCE(LEN(_xlpm.s)),_xlfn.LAMBDA(_xlpm.acc,_xlpm.idx,_xlfn.LET(_xlpm.sk,VALUE(LEFT(_xlpm.acc,FIND("|",_xlpm.acc)-1)),_xlpm.str,MID(_xlpm.acc,FIND("|",_xlpm.acc)+1,9999),IF(_xlpm.sk>0,(_xlpm.sk-1)&"|"&_xlpm.str,_xlfn.LET(_xlpm.ka,MID(_xlpm.s,_xlpm.idx,4),_xlpm.kb,MID(_xlpm.s,_xlpm.idx,3),_xlpm.kc,MID(_xlpm.s,_xlpm.idx,2),_xlpm.kd,MID(_xlpm.s,_xlpm.idx,1),_xlpm.pa,IF(LEN(_xlpm.ka)=4,IFERROR(MATCH(_xlpm.ka,_xlpm.dC,0),0),0),_xlpm.pb,IF(LEN(_xlpm.kb)=3,IFERROR(MATCH(_xlpm.kb,_xlpm.dC,0),0),0),_xlpm.pc,IF(LEN(_xlpm.kc)=2,IFERROR(MATCH(_xlpm.kc,_xlpm.dC,0),0),0),_xlpm.pd,IFERROR(MATCH(_xlpm.kd,_xlpm.dC,0),0),_xlpm.pos,IF(_xlpm.pa>0,_xlpm.pa,IF(_xlpm.pb>0,_xlpm.pb,IF(_xlpm.pc>0,_xlpm.pc,_xlpm.pd))),_xlpm.len,IF(_xlpm.pa>0,4,IF(_xlpm.pb>0,3,IF(_xlpm.pc>0,2,1))),_xlpm.wrd,IF(_xlpm.pos=0,_xlpm.kd,IF(_xlpm.md=1,INDEX(_xlpm.dP,_xlpm.pos),INDEX(_xlpm.dV,_xlpm.pos))),_xlpm.sep,IF(_xlpm.str="","",IF(_xlpm.md=1," "," / ")),(_xlpm.len-1)&"|"&_xlpm.str&_xlpm.sep&_xlpm.wrd))))),MID(_xlpm.res,FIND("|",_xlpm.res)+1,9999)))}
C72: {=IF($A72="","",_xlfn.LET(_xlpm.s,$A72,_xlpm.dC,'📚 Từ Vựng HSK'!$C$4:$C$1025,_xlpm.dP,'📚 Từ Vựng HSK'!$D$4:$D$1025,_xlpm.dV,'📚 Từ Vựng HSK'!$E$4:$E$1025,_xlpm.md,1,_xlpm.res,_xlfn.REDUCE("0|",_xlfn.SEQUENCE(LEN(_xlpm.s)),_xlfn.LAMBDA(_xlpm.acc,_xlpm.idx,_xlfn.LET(_xlpm.sk,VALUE(LEFT(_xlpm.acc,FIND("|",_xlpm.acc)-1)),_xlpm.str,MID(_xlpm.acc,FIND("|",_xlpm.acc)+1,9999),IF(_xlpm.sk>0,(_xlpm.sk-1)&"|"&_xlpm.str,_xlfn.LET(_xlpm.ka,MID(_xlpm.s,_xlpm.idx,4),_xlpm.kb,MID(_xlpm.s,_xlpm.idx,3),_xlpm.kc,MID(_xlpm.s,_xlpm.idx,2),_xlpm.kd,MID(_xlpm.s,_xlpm.idx,1),_xlpm.pa,IF(LEN(_xlpm.ka)=4,IFERROR(MATCH(_xlpm.ka,_xlpm.dC,0),0),0),_xlpm.pb,IF(LEN(_xlpm.kb)=3,IFERROR(MATCH(_xlpm.kb,_xlpm.dC,0),0),0),_xlpm.pc,IF(LEN(_xlpm.kc)=2,IFERROR(MATCH(_xlpm.kc,_xlpm.dC,0),0),0),_xlpm.pd,IFERROR(MATCH(_xlpm.kd,_xlpm.dC,0),0),_xlpm.pos,IF(_xlpm.pa>0,_xlpm.pa,IF(_xlpm.pb>0,_xlpm.pb,IF(_xlpm.pc>0,_xlpm.pc,_xlpm.pd))),_xlpm.len,IF(_xlpm.pa>0,4,IF(_xlpm.pb>0,3,IF(_xlpm.pc>0,2,1))),_xlpm.wrd,IF(_xlpm.pos=0,_xlpm.kd,IF(_xlpm.md=1,INDEX(_xlpm.dP,_xlpm.pos),INDEX(_xlpm.dV,_xlpm.pos))),_xlpm.sep,IF(_xlpm.str="","",IF(_xlpm.md=1," "," / ")),(_xlpm.len-1)&"|"&_xlpm.str&_xlpm.sep&_xlpm.wrd))))),MID(_xlpm.res,FIND("|",_xlpm.res)+1,9999)))} | D72: {=IF($A72="","",_xlfn.LET(_xlpm.s,$A72,_xlpm.dC,'📚 Từ Vựng HSK'!$C$4:$C$1025,_xlpm.dP,'📚 Từ Vựng HSK'!$D$4:$D$1025,_xlpm.dV,'📚 Từ Vựng HSK'!$E$4:$E$1025,_xlpm.md,2,_xlpm.res,_xlfn.REDUCE("0|",_xlfn.SEQUENCE(LEN(_xlpm.s)),_xlfn.LAMBDA(_xlpm.acc,_xlpm.idx,_xlfn.LET(_xlpm.sk,VALUE(LEFT(_xlpm.acc,FIND("|",_xlpm.acc)-1)),_xlpm.str,MID(_xlpm.acc,FIND("|",_xlpm.acc)+1,9999),IF(_xlpm.sk>0,(_xlpm.sk-1)&"|"&_xlpm.str,_xlfn.LET(_xlpm.ka,MID(_xlpm.s,_xlpm.idx,4),_xlpm.kb,MID(_xlpm.s,_xlpm.idx,3),_xlpm.kc,MID(_xlpm.s,_xlpm.idx,2),_xlpm.kd,MID(_xlpm.s,_xlpm.idx,1),_xlpm.pa,IF(LEN(_xlpm.ka)=4,IFERROR(MATCH(_xlpm.ka,_xlpm.dC,0),0),0),_xlpm.pb,IF(LEN(_xlpm.kb)=3,IFERROR(MATCH(_xlpm.kb,_xlpm.dC,0),0),0),_xlpm.pc,IF(LEN(_xlpm.kc)=2,IFERROR(MATCH(_xlpm.kc,_xlpm.dC,0),0),0),_xlpm.pd,IFERROR(MATCH(_xlpm.kd,_xlpm.dC,0),0),_xlpm.pos,IF(_xlpm.pa>0,_xlpm.pa,IF(_xlpm.pb>0,_xlpm.pb,IF(_xlpm.pc>0,_xlpm.pc,_xlpm.pd))),_xlpm.len,IF(_xlpm.pa>0,4,IF(_xlpm.pb>0,3,IF(_xlpm.pc>0,2,1))),_xlpm.wrd,IF(_xlpm.pos=0,_xlpm.kd,IF(_xlpm.md=1,INDEX(_xlpm.dP,_xlpm.pos),INDEX(_xlpm.dV,_xlpm.pos))),_xlpm.sep,IF(_xlpm.str="","",IF(_xlpm.md=1," "," / ")),(_xlpm.len-1)&"|"&_xlpm.str&_xlpm.sep&_xlpm.wrd))))),MID(_xlpm.res,FIND("|",_xlpm.res)+1,9999)))}
C73: {=IF($A73="","",_xlfn.LET(_xlpm.s,$A73,_xlpm.dC,'📚 Từ Vựng HSK'!$C$4:$C$1025,_xlpm.dP,'📚 Từ Vựng HSK'!$D$4:$D$1025,_xlpm.dV,'📚 Từ Vựng HSK'!$E$4:$E$1025,_xlpm.md,1,_xlpm.res,_xlfn.REDUCE("0|",_xlfn.SEQUENCE(LEN(_xlpm.s)),_xlfn.LAMBDA(_xlpm.acc,_xlpm.idx,_xlfn.LET(_xlpm.sk,VALUE(LEFT(_xlpm.acc,FIND("|",_xlpm.acc)-1)),_xlpm.str,MID(_xlpm.acc,FIND("|",_xlpm.acc)+1,9999),IF(_xlpm.sk>0,(_xlpm.sk-1)&"|"&_xlpm.str,_xlfn.LET(_xlpm.ka,MID(_xlpm.s,_xlpm.idx,4),_xlpm.kb,MID(_xlpm.s,_xlpm.idx,3),_xlpm.kc,MID(_xlpm.s,_xlpm.idx,2),_xlpm.kd,MID(_xlpm.s,_xlpm.idx,1),_xlpm.pa,IF(LEN(_xlpm.ka)=4,IFERROR(MATCH(_xlpm.ka,_xlpm.dC,0),0),0),_xlpm.pb,IF(LEN(_xlpm.kb)=3,IFERROR(MATCH(_xlpm.kb,_xlpm.dC,0),0),0),_xlpm.pc,IF(LEN(_xlpm.kc)=2,IFERROR(MATCH(_xlpm.kc,_xlpm.dC,0),0),0),_xlpm.pd,IFERROR(MATCH(_xlpm.kd,_xlpm.dC,0),0),_xlpm.pos,IF(_xlpm.pa>0,_xlpm.pa,IF(_xlpm.pb>0,_xlpm.pb,IF(_xlpm.pc>0,_xlpm.pc,_xlpm.pd))),_xlpm.len,IF(_xlpm.pa>0,4,IF(_xlpm.pb>0,3,IF(_xlpm.pc>0,2,1))),_xlpm.wrd,IF(_xlpm.pos=0,_xlpm.kd,IF(_xlpm.md=1,INDEX(_xlpm.dP,_xlpm.pos),INDEX(_xlpm.dV,_xlpm.pos))),_xlpm.sep,IF(_xlpm.str="","",IF(_xlpm.md=1," "," / ")),(_xlpm.len-1)&"|"&_xlpm.str&_xlpm.sep&_xlpm.wrd))))),MID(_xlpm.res,FIND("|",_xlpm.res)+1,9999)))} | D73: {=IF($A73="","",_xlfn.LET(_xlpm.s,$A73,_xlpm.dC,'📚 Từ Vựng HSK'!$C$4:$C$1025,_xlpm.dP,'📚 Từ Vựng HSK'!$D$4:$D$1025,_xlpm.dV,'📚 Từ Vựng HSK'!$E$4:$E$1025,_xlpm.md,2,_xlpm.res,_xlfn.REDUCE("0|",_xlfn.SEQUENCE(LEN(_xlpm.s)),_xlfn.LAMBDA(_xlpm.acc,_xlpm.idx,_xlfn.LET(_xlpm.sk,VALUE(LEFT(_xlpm.acc,FIND("|",_xlpm.acc)-1)),_xlpm.str,MID(_xlpm.acc,FIND("|",_xlpm.acc)+1,9999),IF(_xlpm.sk>0,(_xlpm.sk-1)&"|"&_xlpm.str,_xlfn.LET(_xlpm.ka,MID(_xlpm.s,_xlpm.idx,4),_xlpm.kb,MID(_xlpm.s,_xlpm.idx,3),_xlpm.kc,MID(_xlpm.s,_xlpm.idx,2),_xlpm.kd,MID(_xlpm.s,_xlpm.idx,1),_xlpm.pa,IF(LEN(_xlpm.ka)=4,IFERROR(MATCH(_xlpm.ka,_xlpm.dC,0),0),0),_xlpm.pb,IF(LEN(_xlpm.kb)=3,IFERROR(MATCH(_xlpm.kb,_xlpm.dC,0),0),0),_xlpm.pc,IF(LEN(_xlpm.kc)=2,IFERROR(MATCH(_xlpm.kc,_xlpm.dC,0),0),0),_xlpm.pd,IFERROR(MATCH(_xlpm.kd,_xlpm.dC,0),0),_xlpm.pos,IF(_xlpm.pa>0,_xlpm.pa,IF(_xlpm.pb>0,_xlpm.pb,IF(_xlpm.pc>0,_xlpm.pc,_xlpm.pd))),_xlpm.len,IF(_xlpm.pa>0,4,IF(_xlpm.pb>0,3,IF(_xlpm.pc>0,2,1))),_xlpm.wrd,IF(_xlpm.pos=0,_xlpm.kd,IF(_xlpm.md=1,INDEX(_xlpm.dP,_xlpm.pos),INDEX(_xlpm.dV,_xlpm.pos))),_xlpm.sep,IF(_xlpm.str="","",IF(_xlpm.md=1," "," / ")),(_xlpm.len-1)&"|"&_xlpm.str&_xlpm.sep&_xlpm.wrd))))),MID(_xlpm.res,FIND("|",_xlpm.res)+1,9999)))}
